Workbook

Sheet Portada
B2: Modelo financiero de la quesería
B3: Lácteos Fúquene · Oferta de IntegraMotion S.A.S.
B5: Documento
B6: Elaboró | C6: IntegraMotion S.A.S. · Producción y evaluación económica
B7: Curso | C7: Automatización de Procesos de Manufactura · 2026-2S · Universidad Nacional de Colombia
B8: Unidades | C8: Millones de pesos constantes de 2026, salvo donde se indique
B9: Estado de los chequeos | C9: =Chequeos!$C$43 -> OK
B10: Chequeos en OK | C10: =Chequeos!$B$43 -> 36 de 36
B12: Resultados de la oferta
B13: Costo de capital del proyecto | C13: =Quesería!B178 -> 0.1470725 | D13: Crédito de fomento más garantía, después de impuestos, y capital propio al 25 %.
B14: TIR del proyecto en pesos corrientes | C14: =Quesería!B179 -> 0.24327136 | D14: Se compara con el costo de capital.
B15: TIR del proyecto en pesos constantes | C15: =Quesería!B180 -> 0.19238125 | D15: Se compara con la tasa real equivalente.
B16: Tasa real equivalente | C16: =Quesería!B181 -> 0.099609054 | D16: Costo de capital sin la inflación promedio de 2027 a 2037 (hoja Entorno).
B17: VPN a 10 años al costo de capital ($ M de 2026) | C17: =Quesería!B182 -> 639.5567 | D17: Valor que crea el proyecto después de pagar el capital.
B18: Recuperación simple (años) | C18: =Quesería!B183 -> 4.6824017 | D18: Años hasta recuperar la inversión con los flujos sin descontar.
B19: Recuperación descontada (años) | C19: =Quesería!B184 -> 6.4410043 | D19: Lo mismo, con los flujos descontados al costo de capital.
B20: TIR del inversionista en pesos corrientes | C20: =Quesería!B186 -> 0.42102438 | D20: Se compara con el 25 % que exige el socio.
B21: Cobertura mínima del servicio de la deuda | C21: =Quesería!B189 -> 1.3435688 | D21: Del proyecto solo, con el prepago de 10 % del saldo en 2029; la empresa completa en la hoja Empresa.
B22: VPN si no se obtiene el crédito fiscal por innovación ($ M) | C22: =Escenarios!$T$37 -> 402.88946 | D22: La oferta incluye la gestión del crédito. Sin la certificación el proyecto todavía crea valor, aunque poco, y el dueño gana menos del 25 % que pide: la gestión es parte de la oferta, no un extra.
B23: VPN si la primera compuerta no se supera ($ M) | C23: =Herramientas!B80 -> -48.867085 | D23: Se paga el contrato principal completo y las herramientas de la etapa 0, sin comprar equipos. Es la pérdida que se acepta con los ahorros conservadores de la etapa 0; sensibilidad en la hoja Herramientas.
B24: Deuda total / EBITDA más alta de la empresa | C24: =Empresa!$B$41 -> 1.2478296 | D24: Con el crédito del proyecto.
B25: Inversión total ($ M de 2026) | C25: =Quesería!$F$97 -> 1589.2693 | D25: Con imprevistos, sin IVA.
B26: Beneficio anual pleno ($ M de 2026) | C26: =Quesería!$E$128 -> 568.06498 | D26: A salarios de 2026; los ahorros de mano de obra crecen con el salario mínimo real.
B28: Contenido
B29: Resumen | C29: Los cuadros que se presentan: costo total, costo de ingeniería, cronograma, BOM, beneficios, flujo, indicadores y escenarios.
B30: Quesería | C30: Supuestos, inversión, beneficios, flujo de caja, crédito y resultados de la oferta.
B31: Entorno | C31: Inflación y salario mínimo de 2027 a 2037 y lectura política y económica, con fuentes.
B32: Beneficios y costos | C32: Balance de masa de los quesos, cálculo de cada beneficio, cómo se mide cada uno (matriz de trazabilidad) y costos operativos nuevos (energía, vapor y calibración).
B33: Cotizaciones | C33: Precios de referencia de los equipos y tasas de cambio.
B34: BOM | C34: Lista de materiales del diseño técnico, valorada ítem por ítem y enlazada a la inversión.
B35: Escenarios | C35: La evaluación completa con los supuestos que más mueven el resultado.
B36: Riesgo | C36: Punto de equilibrio, gráfico de tornado, escenarios clave y plan de respuesta a los riesgos (señal, estrategia, responsable y recursos).
B37: Herramientas | C37: Herramientas económicas una sobre otra, beneficios tributarios y qué pasa si no se aprueban, valor de cada etapa y protecciones en los contratos.
B38: Empresa | C38: Efecto en el estado de resultados y el endeudamiento de Lácteos Fúquene.
B39: IntegraMotion | C39: Horas y precio del contrato principal y los dos otrosíes por paquete de la EDT, control del contrato principal por valor ganado (curva S), gastos de funcionamiento, entregables y plan de negocio.
B40: APU | C40: Análisis de precios unitarios de la ingeniería.
B41: Chequeos | C41: Diferencias que deben dar cero.
B43: Cómo se lee
B44: Texto azul | C44: Dato de entrada: se puede cambiar.
B45: Texto negro | C45: Fórmula: no se escribe encima.
...

Sheet Resumen
A1: Resumen del proyecto: automatización de la quesería de Lácteos Fúquene
A2: Oferta de IntegraMotion S.A.S. Millones de pesos constantes de 2026, sin IVA, salvo donde se indique. Todas las cifras salen de las demás hojas del modelo.
A4: Las tres cifras que hay que saber
A5: Costo total del proyecto | E5: Costo de ingeniería | I5: Cronograma
A6: =Quesería!$B$191 -> 1589.2693 | E6: =IntegraMotion!$I$149 -> 376.01435 | I6: 16 semanas
A7: Inversión del año 0 (semestre 2026-2 y 2027) y de 2028, con imprevistos: equipos del BOM, ingeniería, ERP, formación y aval. | E7: Lo que Lácteos Fúquene le paga a IntegraMotion: contrato principal y dos otrosíes. | I7: Contrato principal en el semestre 2026-2; otrosí 1 en marzo y abril de 2027 y otrosí 2 en 2028, si se superan las compuertas.
A9: Presupuesto del proyecto (costo para Lácteos Fúquene)
A10: Rubro ($ M constantes de 2026) | B10: Año 0: 2026-2 y 2027 (etapas 0 y 1) | C10: 2028 (etapa 2) | D10: Total
A11: Equipos, instrumentos, control y herramientas (del BOM) | B11: =Quesería!$F$70*(Quesería!$C$70=0)+Quesería!$F$71*(Quesería!$C$71=0)+Quesería!$F$72*(Quesería!$C$72=0)+Quesería!$F$73*(Quesería!$C$73=0)+Quesería!$F$74*(Quesería!$C$74=0)+Quesería!$F$75*(Quesería!$C$75=0)+Quesería!$F$84*(Quesería!$C$84=0)+Quesería!$F$85*(Quesería!$C$85=0)+Quesería!$F$86*(Quesería!$C$86=0)+Quesería!$F$87*(Quesería!$C$87=0) -> 484.36567 | C11: =Quesería!$F$70*(Quesería!$C$70=1)+Quesería!$F$71*(Quesería!$C$71=1)+Quesería!$F$72*(Quesería!$C$72=1)+Quesería!$F$73*(Quesería!$C$73=1)+Quesería!$F$74*(Quesería!$C$74=1)+Quesería!$F$75*(Quesería!$C$75=1)+Quesería!$F$84*(Quesería!$C$84=1)+Quesería!$F$85*(Quesería!$C$85=1)+Quesería!$F$86*(Quesería!$C$86=1)+Quesería!$F$87*(Quesería!$C$87=1) -> 488.78187 | D11: =B11+C11 -> 973.14753
A12: Ingeniería de IntegraMotion | B12: =Quesería!$F$76*(Quesería!$C$76=0)+Quesería!$F$77*(Quesería!$C$77=0)+Quesería!$F$78*(Quesería!$C$78=0)+Quesería!$F$79*(Quesería!$C$79=0)+Quesería!$F$88*(Quesería!$C$88=0) -> 289.95616 | C12: =Quesería!$F$76*(Quesería!$C$76=1)+Quesería!$F$77*(Quesería!$C$77=1)+Quesería!$F$78*(Quesería!$C$78=1)+Quesería!$F$79*(Quesería!$C$79=1)+Quesería!$F$88*(Quesería!$C$88=1) -> 90.106032 | D12: =B12+C12 -> 380.06219
A13: Parametrización del ERP por su proveedor, formación con el SENA y aval del proyecto de innovación | B13: =Quesería!$F$80*(Quesería!$C$80=0)+Quesería!$F$81*(Quesería!$C$81=0)+Quesería!$F$82*(Quesería!$C$82=0) -> 46.666667 | C13: =Quesería!$F$80*(Quesería!$C$80=1)+Quesería!$F$81*(Quesería!$C$81=1)+Quesería!$F$82*(Quesería!$C$82=1) -> 0 | D13: =B13+C13 -> 46.666667
A14: Imprevistos según la madurez de cada precio | B14: =Quesería!$F$83*(Quesería!$C$83=0)+Quesería!$F$89*(Quesería!$C$89=0) -> 109.81175 | C14: =Quesería!$F$83*(Quesería!$C$83=1)+Quesería!$F$89*(Quesería!$C$89=1) -> 79.581168 | D14: =B14+C14 -> 189.39292
A15: Costo total del proyecto | B15: =SUM(B11:B14) -> 930.80024 | C15: =SUM(C11:C14) -> 658.46907 | D15: =SUM(D11:D14) -> 1589.2693
A16: Comprobación: total − inversión de la hoja Quesería | D16: =D15-Quesería!$B$191 -> 0
A18: Costo de ingeniería por contrato
A19: Contrato ($ M de 2026, sin reajuste) | B19: Plazo | C19: Horas | D19: Costo para IntegraMotion | E19: Costo de ingeniería del proyecto | F19: Con IVA
A20: Contrato principal: los 19 paquetes de la EDT | B20: 16 semanas | C20: =IntegraMotion!$H$139 -> 2680.5912 | D20: =IntegraMotion!$H$145 -> 160.71471 | E20: =IntegraMotion!$H$149 -> 223.39345 | F20: =IntegraMotion!$H$151 -> 265.8382
A21: Otrosí 1: implementación de la etapa 1 | B21: 2 meses | C21: =IntegraMotion!$F$139 -> 611.6 | D21: =IntegraMotion!$F$145 -> 46.783459 | E21: =IntegraMotion!$F$149 -> 65.029008 | F21: =IntegraMotion!$F$151 -> 77.38452
A22: Otrosí 2: detalle e implementación de la etapa 2 | B22: 2 meses | C22: =IntegraMotion!$G$139 -> 1004.8425 | D22: =IntegraMotion!$G$145 -> 63.015753 | E22: =IntegraMotion!$G$149 -> 87.591896 | F22: =IntegraMotion!$G$151 -> 104.23436
A23: Total | C23: =SUM(C20:C22) -> 4297.0337 | D23: =SUM(D20:D22) -> 270.51392 | E23: =SUM(E20:E22) -> 376.01435 | F23: =SUM(F20:F22) -> 447.45708
A24: Reajuste real de los otrosíes: se liquidan con el salario mínimo del año en que se ejecutan, que sube más que la inflación | E24: =D12-E23 -> 4.0478383
A25: Ingeniería en el presupuesto del proyecto, en pesos constantes de 2026 | E25: =D12 -> 380.06219
A26: Para IntegraMotion, el costo es lo que gasta (honorarios, conocimiento certificado, viajes e instrumentos) y el precio es lo que cobra: costo más administración, imprevistos y utilidad (AIU). Ese precio es el costo de ingeniería del proyecto para Lácteos Fúquene y entra a la inversión.
A28: Equipos del BOM por rubro
A29: Rubro | B29: Etapa | C29: Ítems | D29: Valor del BOM | E29: Parte de la quesería | F29: A la inversión
A30: =BOM!A72 -> Etapa 0: herramientas de mantenimiento y medición | B30: =BOM!C72 -> 0 | C30: =BOM!E72 -> 6 | D30: =BOM!F72 -> 56.872528 | E30: =BOM!H72 -> 0.36 | F30: =BOM!I72 -> 20.47411
A31: =BOM!A73 -> Tinas TQ-301 y TQ-303, control y tablero | B31: =BOM!C73 -> 1 | C31: =BOM!E73 -> 19 | D31: =BOM!F73 -> 267.50965 | E31: =BOM!H73 -> 1 | F31: =BOM!I73 -> 267.50965
A32: =BOM!A74 -> Tina TQ-302 del doble crema | B32: =BOM!C74 -> 1 | C32: =BOM!E74 -> 6 | D32: =BOM!F74 -> 47.746861 | E32: =BOM!H74 -> 1 | F32: =BOM!I74 -> 47.746861
A33: =BOM!A75 -> Estación E18 de inspección | B33: =BOM!C75 -> 1 | C33: =BOM!E75 -> 1 | D33: =BOM!F75 -> 33.178864 | E33: =BOM!H75 -> 1 | F33: =BOM!I75 -> 33.178864
A34: =BOM!A76 -> Estandarización de grasa (recepción) | B34: =BOM!C76 -> 1 | C34: =BOM!E76 -> 2 | D34: =BOM!F76 -> 129.98093 | E34: =BOM!H76 -> 0.36 | F34: =BOM!I76 -> 46.793136
A35: =BOM!A77 -> SCADA, historiador y MES | B35: =BOM!C77 -> 1 | C35: =BOM!E77 -> 11 | D35: =BOM!F77 -> 130.79213 | E35: =BOM!H77 -> 0.5249784 | F35: =BOM!I77 -> 68.663043
A36: =BOM!A78 -> Hiladora E13 | B36: =BOM!C78 -> 2 | C36: =BOM!E78 -> 1 | D36: =BOM!F78 -> 322.6 | E36: =BOM!H78 -> 1 | F36: =BOM!I78 -> 322.6
A37: =BOM!A79 -> CIP del circuito de quesos | B37: =BOM!C79 -> 2 | C37: =BOM!E79 -> 1 | D37: =BOM!F79 -> 106.66667 | E37: =BOM!H79 -> 1 | F37: =BOM!I79 -> 106.66667
A38: =BOM!A80 -> Suero | B38: =BOM!C80 -> 2 | C38: =BOM!E80 -> 1 | D38: =BOM!F80 -> 80 | E38: =BOM!H80 -> 0 | F38: =BOM!I80 -> 0
A39: =BOM!A81 -> Instrumentación y control de la etapa 2 | B39: =BOM!C81 -> 2 | C39: =BOM!E81 -> 4 | D39: =BOM!F81 -> 59.5152 | E39: =BOM!H81 -> 1 | F39: =BOM!I81 -> 59.5152
A40: Total que entra a la inversión, sin imprevistos | C40: =SUM(C30:C39) -> 52 | F40: =SUM(F30:F39) -> 973.14753
A41: Celda de paletizado (se diseña en el contrato principal; su compra es una etapa 3 fuera de la evaluación) | D41: =BOM!F82 -> 521.38215
A43: Beneficios anuales en régimen
A44: Medida | B44: Etapa | C44: Beneficio | D44: Respaldo (1 a 5)
A45: =Quesería!A104 -> Horas extra del hilado evitadas con el orden del hilado (0,5 h/día) | B45: =Quesería!B104 -> 1 | C45: =Quesería!E104 -> 11.76 | D45: =Quesería!H104 -> 3
...

Sheet Quesería
A1: Modelo financiero de la quesería — Lácteos Fúquene
A2: Oferta de IntegraMotion S.A.S. Millones de pesos constantes de 2026. Texto azul: datos de entrada; negro: fórmulas; fondo amarillo: cifras clave.
A4: Supuestos
A5: Supuesto | B5: Valor | C5: Unidad | D5: Fuente o criterio
A6: Tasas e inflación
A7: Ruta de inflación (1 base, 2 consenso de los analistas, 3 persistente) | B7: 1 | C7: ruta | D7: Hoja Entorno: inflación de cada año de 2027 a 2037.
A8: Costo de capital de la empresa con su deuda actual | B8: 0.16 | C8: % | D8: 70 % deuda al 18 % (intereses / deuda de 2026: 252 / 1.400) y 30 % capital propio al 25 %. Es la referencia de la primera entrega.
A9: Costo de capital del proyecto en pesos corrientes | B9: =$B$44*($B$45+$B$49*$B$51*1.19)*(1-$B$54)+(1-$B$44)*$B$11 -> 0.1470725 | C9: % | D9: Con la deuda que de verdad financia el proyecto: crédito de fomento más la comisión de la garantía, después de impuestos (70 %), y capital propio al 25 % (30 %). Con él se descuentan los flujos.
A10: Tasa real equivalente | B10: =(1+$B$9)/(1+CHOOSE($B$7,Entorno!$M$7,Entorno!$M$8,Entorno!$M$9))-1 -> 0.099609054 | C10: % | D10: El costo de capital sin la inflación promedio de la ruta; con ella se compara la TIR en pesos constantes.
A11: Rentabilidad que exige el inversionista en pesos corrientes | B11: 0.25 | C11: % | D11: Lo que espera ganar el socio por arriesgar su capital.
A12: Rentabilidad exigida real equivalente | B12: =(1+$B$11)/(1+CHOOSE($B$7,Entorno!$M$7,Entorno!$M$8,Entorno!$M$9))-1 -> 0.19827763 | C12: % | D12: Misma conversión de la tasa de descuento.
A13: Operación de la planta y reparto
A14: Leche de la quesería | B14: 9000 | C14: L/día | D14: Reparto de la leche de la planta.
A15: Leche de la planta | B15: 25000 | C15: L/día | D15: Caso de estudio.
A16: Parte de la quesería en la leche | B16: =$B$14/$B$15 -> 0.36 | C16: % | D16: Reparte la grasa en línea, el mantenimiento y la etapa 0.
A17: Ventas de la quesería | B17: 6772 | C17: $ M/año | D17: Caso de estudio (294 días de operación).
A18: Ventas de la planta | B18: 30457 | C18: $ M/año | D18: Caso de estudio.
A19: Parte de la quesería en las ventas | B19: =$B$17/$B$18 -> 0.22234626 | C19: % | D19: Reparte la reducción de merma.
A20: Beneficio del primer año de cada etapa | B20: 0.75 | C20: % del pleno | D20: Arranque, ajuste de recetas y formación.
A21: Meses de operación de la etapa 1 en 2027 | B21: 8 | C21: meses | D21: El contrato principal son las 16 semanas del semestre 2026-2 y cierra con la primera compuerta en diciembre de 2026. Los equipos se compran en enero y el otrosí 1 (montaje y puesta en marcha) va en marzo y abril: la etapa 1 opera desde mayo de 2027. Se cuentan 8 meses con el beneficio de arranque; la compuerta de diciembre de 2027 usa esos datos medidos.
A22: Costo anual de un operario | B22: 36 | C22: $ M/año | D22: Salario, prestaciones y aportes.
A23: Meses de traslape mientras se forman los operarios de la hiladora | B23: 3 | C23: meses | D23: Los 2 operarios que se reubican siguen en el hilado hasta que la hiladora opera sola, mientras se forman para su nuevo puesto; la producción no cae en ese tiempo.
A24: Costo de reemplazar a un operario con alguien de afuera | B24: 0.3 | C24: % del costo anual | D24: Reclutamiento, vacante y curva de aprendizaje: 30 a 50 % del salario anual (Semana, febrero de 2026). Se evita al cubrir el puesto con personal de la planta.
A25: Inversión, imprevistos y reposición
A26: Imprevistos: precio cerrado (contratos y SENA) | B26: 0.05 | C26: % del rubro | D26: Clasificación de estimados AACE 18R-97: la contingencia baja a medida que el precio madura. Solo cubre cambios de alcance.
A27: Imprevistos: precio publicado de catálogo | B27: 0.1 | C27: % del rubro | D27: Falta la cotización formal y el flete real.
A28: Imprevistos: estimado con referencias de mercado | B28: 0.15 | C28: % del rubro | D28: Equipos con precios de referencia de máquinas parecidas (hoja Cotizaciones).
A29: Imprevistos: estimado sin cotización | B29: 0.25 | C29: % del rubro | D29: Estimado de orden de magnitud (clase 4 a 5 de AACE).
A30: Vida fiscal de maquinaria y equipo | B30: 10 | C30: años | D30: Línea recta, 10 % anual (art. 137 ET). La de cada rubro está en la tabla de inversión.
A31: Mantenimiento de equipos nuevos | B31: 0.03 | C31: % equipos/año | D31: Práctica de la industria para equipos de proceso.
A32: Suscripciones de software del SCADA de la quesería | B32: 13.6 | C32: $ M/año | D32: Licencias de SCADA, historiador y analítica dimensionadas para una línea (12,0) y renovación de la protección del firewall (unos US$1.435 al año, 36 % a la quesería: 1,6).
A33: Póliza todo riesgo de los equipos nuevos | B33: 0.0025 | C33: % equipos/año | D33: El banco la pide endosada a su favor. Supuesto; se cotiza.
A34: Reposición del hardware del SCADA en el año 5 | B34: 0.4 | C34: % del rubro SCADA | D34: Servidor, red y estaciones (vida fiscal de 5 años); las licencias siguen en las suscripciones.
A35: Reposición parcial de instrumentación en el año 6 | B35: 0.1 | C35: % de los equipos de la etapa 1 | D35: Sensores, celdas de carga y sondas en ambiente húmedo y con lavados.
A36: Valor de los equipos al año 10 | B36: 0.1 | C36: % de su costo | D36: Se vende o se toma como parte de pago; se grava completo.
A37: Capital de trabajo
A38: Días de cartera sobre las ventas adicionales | B38: 30 | C38: días | D38: Política comercial de la planta. El capital de trabajo suma cartera e inventario al costo y resta las cuentas por pagar; se recupera al final del horizonte.
A39: Días de inventario del queso adicional | B39: 5 | C39: días | D39: Queso fresco: se despacha en la semana. Se valora al costo, no al precio.
A40: Costo de ventas sobre ventas | B40: 0.82 | C40: % | D40: Estado de resultados del caso: leche, insumos, nómina, energía y mantenimiento sobre las ventas.
A41: Costo variable sobre ventas (lo que se evita al no perder producto) | B41: 0.688 | C41: % | D41: Estado de resultados del caso: leche (47,8 %), insumos y empaques (17,0 %) y energía, agua, gas y químicos (4,0 %). La nómina y el mantenimiento no cambian si se pierde menos producto.
...

Sheet Entorno
A1: Entorno económico y político del proyecto
A2: La quesería se ejecuta en 2027 y 2028 y opera hasta 2037. Precios en pesos de 2026; esta hoja dice cuánto cambian año por año la inflación y el salario mínimo.
A4: Inflación y salario mínimo, año por año
B5: Año 0 | C5: Año 1 | D5: Año 2 | E5: Año 3 | F5: Año 4 | G5: Año 5 | H5: Año 6 | I5: Año 7 | J5: Año 8 | K5: Año 9 | L5: Año 10 | M5: Promedio
A6: Año calendario | B6: 2027 | C6: 2028 | D6: 2029 | E6: 2030 | F6: 2031 | G6: 2032 | H6: 2033 | I6: 2034 | J6: 2035 | K6: 2036 | L6: 2037
A7: Ruta 1 · base: inflación de cada año | B7: 0.06 | C7: 0.05 | D7: 0.045 | E7: 0.04 | F7: 0.04 | G7: 0.04 | H7: 0.04 | I7: 0.04 | J7: 0.04 | K7: 0.04 | L7: 0.04 | M7: =EXP(SUMPRODUCT(LN(1+B7:L7))/11)-1 -> 0.043163928
A8: Ruta 2 · consenso de los analistas | B8: 0.059 | C8: 0.045 | D8: 0.037 | E8: 0.034 | F8: 0.034 | G8: 0.034 | H8: 0.034 | I8: 0.034 | J8: 0.034 | K8: 0.034 | L8: 0.034 | M8: =EXP(SUMPRODUCT(LN(1+B8:L8))/11)-1 -> 0.037518712
A9: Ruta 3 · inflación persistente | B9: 0.065 | C9: 0.065 | D9: 0.065 | E9: 0.065 | F9: 0.065 | G9: 0.065 | H9: 0.065 | I9: 0.065 | J9: 0.065 | K9: 0.065 | L9: 0.065 | M9: =EXP(SUMPRODUCT(LN(1+B9:L9))/11)-1 -> 0.065
A10: Promedio geométrico de 2027 a 2037. La ruta que usa el modelo se elige en los supuestos de la hoja Quesería.
A12: Incremento del salario mínimo para 2027 | B12: 0.085 | D12: Davivienda: inflación de 2026 (6,91 %) − productividad (0,32 %) + «sorpresa política» (1,91 %). Gremios: 8 % a 9,5 %; Credicorp: 9 % a 10 %.
A13: Aumento real del salario mínimo desde 2028 | B13: 0.005 | D13: El Gobierno plantea volver a ajustarlo por inflación y productividad; la productividad del trabajo ha estado cerca de cero.
A14: Salario mínimo real de 2027 con la ruta base (2026 = 1) | B14: =(1+B12)/(1+B7) -> 1.0235849 | D14: Cuánto sube por encima de la inflación.
A15: Salario mínimo real de 2028 con la ruta base (2026 = 1) | B15: =B14*(1+B13) -> 1.0287028 | D15: Reajusta los contratos de IntegraMotion: la etapa 2 se ejecuta en 2028.
A16: Salario mínimo de 2027 en pesos | B16: =1750905*(1+B12) -> 1899731.9 | D16: Decreto de 2026: $1.750.905.
A17: Afecta lo que depende del salario: horas extra y reubicación de operarios (beneficios), traslape del personal y honorarios de IntegraMotion.
A19: Cómo se armaron las rutas
A20: • Encuesta de analistas del Banco de la República (septiembre de 2026): 6,8 % al cierre de 2026, 5,1 % al cierre de 2027, 4,0 % en agosto de 2028 y 3,4 % a cinco años. Los analistas han subido su pronóstico casi todos los meses de 2026.
A21: • Inflación de septiembre de 2026: 6,29 % anual (DANE), la más alta desde julio de 2024. Tasa del Banco de la República: 12,25 % desde el 1 de octubre, con una subida de 25 puntos básicos y la junta dividida.
A22: • Rutas en promedio de cada año. Consenso: de 6,8 % en diciembre de 2026 a 5,1 % en diciembre de 2027 da 5,9 % para 2027; luego 4,5 %, 3,7 % y 3,4 %. Ruta base: por encima del consenso cada año, con más margen desde 2028, y 4 % desde 2030, el techo del rango de la meta (2 % a 4 %). Ruta persistente: la inflación se queda cerca del dato de septiembre todo el horizonte.
A24: Lectura política y económica (octubre de 2026)
A25: • Salario mínimo: en 2026 subió 23,7 %, muy por encima de la inflación. El Gobierno de Abelardo de la Espriella y su ministro de Hacienda piden volver a un ajuste técnico (inflación más productividad); los analistas esperan 8 % a 10 % para 2027 por una prima política. La decisión se toma a más tardar el 30 de diciembre.
A26: • Presupuesto General de 2027: el Congreso lo aprobó el 20 de octubre por $634,9 billones, pero quedó en vilo por un presunto vicio de trámite en el artículo 65 (Senado y Cámara habrían aprobado textos distintos); si se confirma, el Gobierno lo expide por decreto. Suma incertidumbre fiscal: hace menos probable que las tasas de interés bajen rápido.
A27: • Política monetaria: el Banco de la República volvió a subir la tasa en septiembre. Davivienda espera bajadas graduales hasta 11 % al cierre de 2027. El crédito de fomento se pacta sobre la IBR más un margen, así que sigue esa tendencia.
A28: • Impuestos: el Gobierno anunció una reforma para bajar la carga de las empresas, sin tarifa definida todavía. El modelo deja la renta en 35 % y prueba 30 % en la hoja Escenarios.
A29: • Energía: el gas para la industria depende cada vez más de importaciones y El Niño presiona las tarifas. La hoja Escenarios prueba costos operativos 30 % más altos.
A31: Cómo entra al modelo
... A43: • Presupuesto de 2027 aprobado y en vilo: portafolio.co/economia/gobierno/presupuesto-de-2027-recien-aprobado-en-vilo-por-inminente-hundimiento-por-vicio-de-tramite-en-el-congreso-504829

Sheet Beneficios y costos
A1: Beneficios y costos operativos de la quesería
A2: Cada beneficio sale del balance de masa, de los precios y de la mejora que se espera; cada costo nuevo, del consumo de los equipos. $ M constantes de 2026. Las cifras en azul se miden en la etapa 0.
A4: Datos de la operación
A5: Dato | B5: Valor | C5: Unidad | D5: Fuente o criterio
A6: Días de operación al año | B6: 294 | C6: días | D6: Caso: lunes a sábado menos festivos.
A7: Densidad de la leche | B7: 1.03 | C7: kg/L | D7: Valor típico.
A8: Grasa de la leche cruda | B8: 0.036 | C8: % m/m | D8: Hato Holstein de la sabana de Ubaté.
A9: Grasa de la crema | B9: 0.4 | C9: % m/m | D9: Descremadora centrífuga.
A10: Grasa de más que se deja hoy al estandarizar a mano | B10: 0.0008 | C10: puntos | D10: Cuadro de Pearson y muestreo: el operario deja margen para no quedar por debajo del mínimo.
A11: Grasa de más con el medidor en línea | B11: 0.0003 | C11: puntos | D11: Medidor de grasa y densidad con válvula de remezcla.
A12: Crema añadida al fundido del doble crema | B12: 30 | C12: kg/día | D12: Sale de la crema de la estandarización.
A13: Agua de lavado del grano del campesino | B13: 0.03 | C13: kg/kg leche | D13: Sale con el suero.
A14: Queso adicional por el corte con sensor de coagulación | B14: 0.0015 | C14: kg/kg leche | D14: Menos finos al suero en el campesino y la mozzarella (0,15 puntos de rendimiento).
A15: Queso adicional con la hiladora-moldeadora | B15: 0.02 | C15: % del queso hilado | D15: Menos grasa y finos al agua de hilado que en la marmita a mano.
A16: Sobrepeso de los quesos hoy | B16: 0.01 | C16: % del peso | D16: Igual al de las bolsas UHT del caso.
A17: Sobrepeso con la controladora de peso | B17: 0.005 | C17: % del peso | D17: La controladora rechaza y ajusta el corte.
... A24: Ahorro con limpieza CIP automática | B24: 0.1 | C24: % de ese gasto | D24: Recuperación de soluciones y ciclos medidos en lugar de lavado a mano.
A25: Parte del circuito de quesos en la limpieza | B25: =1/3 -> 0.33333333 | C25: % | D25: Uno de los tres circuitos (quesos, yogur y UHT).
A26: Horas extra diarias del hilado que se evitan en cada etapa | B26: 0.5 | C26: h/día | D26: VSM: el hilado a mano necesita 8,4 h en una ventana de 7,4 h.
A27: Operarios del hilado | B27: 4 | C27: personas | D27: Dos parejas.
A28: Costo de la hora extra | B28: 20000 | C28: $/h | D28: Costo de la hora de un salario mínimo más el recargo de 25 %.
A29: Precio de la crema vendida | B29: 9000 | C29: $/kg | D29: Crema al 40 % a granel.
A30: Precio de la leche entera UHT | B30: 3100 | C30: $/L | D30: Precio a distribuidor del caso.
A31: Precio del suero hoy, sin enfriar | B31: 30 | C31: $/kg | D31: Caso de estudio.
A32: Precio del suero enfriado con contrato | B32: 45 | C32: $/kg | D32: Contrato anual con una fábrica de alimento balanceado; se valida en la etapa 0 con dos cotizaciones.
A33: Ventas de la quesería que hoy salen incompletas o tarde por paros que Ventas no conoce | B33: 0.01 | C33: % ventas de quesos | D33: Caso de estudio, hallazgo H9 (registro de despachos de 2026): Ventas promete sin saber qué máquinas están en falla.
A34: Descuento con que se coloca ese queso en otro cliente o canal | B34: 0.3 | C34: % del precio | D34: Caso de estudio: el queso fresco que no sale a tiempo se coloca en mayoristas con descuento.
A35: Parte de esos incumplimientos que se evita con el estado de la planta en el ERP | B35: =2/3 -> 0.66666667 | C35: % | D35: Estimado: los paros siguen ocurriendo, pero Ventas los ve en el ERP y promete con la capacidad real.
A36: Horas al día de supervisores y planeador conciliando registros de papel y Excel | B36: 1.5 | C36: h/día | D36: Caso de estudio, hallazgo H9: planeación semanal en Excel y registros en papel. El MES los registra solos; el tiempo liberado se usa en mejora.
A37: Costo de una hora de supervisor | B37: 29000 | C37: $/h | D37: Salario de unos $3,5 M al mes con factor prestacional de 1,52, entre 182 horas.
A38: Ventas del yogur | B38: 9851 | C38: $ M/año | D38: Caso de estudio.
A39: Ventas del UHT | B39: 12315 | C39: $ M/año | D39: Caso de estudio.
A40: Yogur que se sobreacidifica o se reprocesa (H2) | B40: 0.02 | C40: % de la producción | D40: Caso de estudio.
A41: Sobrellenado de los vasos de yogur (H3) | B41: 0.02 | C41: % del peso | D41: Caso de estudio.
A42: Sobrellenado de las bolsas de UHT (H3) | B42: 0.01 | C42: % del volumen | D42: Caso de estudio.
A43: Producto perdido en las interfases del UHT (H4) | B43: 0.01 | C43: % del volumen | D43: Caso de estudio.
A44: Operarios liberados que cubren un puesto que la planta tendría que contratar | B44: 1 | C44: personas | D44: Hallazgo H10 de la etapa 0: el plan preventivo necesita un puesto de mantenimiento autónomo (inspección, lubricación y limpieza técnica) que hoy no existe. La asignación por competencias pone ahí a uno de los operarios que libera la hiladora.
A45: Queso adicional con el balance de sólidos y la humedad controlados por lote | B45: 0.005 | C45: % del queso | D45: Hallazgo H11 de la etapa 0. Por la fórmula de Van Slyke el rendimiento va con 1/(1 − humedad): subir la humedad promedio 0,25 puntos dentro de la norma del queso (de 50,00 a 50,25 %) da 0,5 % más queso; también sale de llevar a la mediana los lotes que hoy pierden más grasa y proteína al suero. La etapa 0 mide la dispersión real con un mes de lotes. No incluye el sensor ni la hiladora.
A46: Lo que puede bajar la leche de cada queso frente a hoy | B46: 0.15 | C46: % de su leche | D46: Hallazgo H12. Bajar la producción de un queso no tiene límite de mercado; se limita para no perder clientes del campesino.
A47: Lo que el mercado absorbe de más de campesino | B47: 0.05 | C47: % de su producción | D47: Estudio de mercado de la empresa (tabla de esta hoja): el campesino no sube en la mezcla óptima porque es el que menos deja por litro.
...

Sheet Cotizaciones
A1: Cotizaciones y precios de referencia de los equipos
A2: Precios publicados en octubre de 2026, convertidos a pesos con la TRM y el euro del día. Sin cotización formal todavía: las cifras en azul se reemplazan cuando lleguen las de los proveedores.
A4: Tasas de cambio y factores
A5: Concepto | B5: Valor | C5: Unidad | D5: Fuente
A6: Tasa representativa del mercado (16 de octubre de 2026) | B6: 3170.46 | C6: $/US$ | D6: Superintendencia Financiera, citada por Noticias Caracol, 16-oct-2026.
A7: Euro en pesos (15 de octubre de 2026) | B7: 3569.9 | C7: $/€ | D7: Investing.com, citado por Portafolio, 15-oct-2026.
A8: Flete, seguro, arancel y nacionalización de un equipo importado | B8: 0.3 | C8: % del precio | D8: Supuesto: flete marítimo e internación desde Asia o Europa; confirmar con el agente de aduanas.
A9: Instalación, integración y puesta en marcha | B9: 0.15 | C9: % del precio | D9: Supuesto: montaje, cableado al PLC y pruebas en sitio.
A11: Equipos de la inversión
A12: Equipo | B12: Precio de referencia | C12: Moneda | D12: Precio en $ M | E12: Con nacionalización e instalación ($ M) | F12: Valor en el modelo ($ M) | G12: Estado | H12: Referencia | I12: Lectura
A13: Controladora de peso y detector de metales (estación E18) | B13: 7000 | C13: US$ | D13: =B13*$B$6/1000000 -> 22.19322 | E13: =D13*(1+$B$8)*(1+$B$9) -> 33.178864 | F13: =E13 -> 33.178864 | G13: Precio publicado | H13: Made-in-China, catálogo de controladoras de peso: equipo combinado con detector de metales, US$6.500–7.000 por unidad (oct-2026). | I13: Equipo de origen chino. Una marca europea puede costar 3 a 4 veces más; se recomienda pedir las dos cotizaciones.
A14: Hiladora-moldeadora continua de 300 kg/h | B14: 39000 | C14: € | D14: =B14*$B$7/1000000 -> 139.2261 | E14: =D14*(1+$B$8)*(1+$B$9) -> 208.14302 | F14: 322.6 | G14: Estimado con referencias | H14: Werktuigen: DIMA 100 Compact usada (2023), 100 kg/h, €39.000. Ullmer's: cocedora-hiladora DIMA usada, US$35.000. Made-in-China: cocedora-hiladora por lotes, US$12.500–18.500. | I14: Las referencias son de máquinas usadas de 100 kg/h o de equipos por lotes. Una continua nueva de 300 kg/h (Milkylab, CMT, Dima) es de precio a solicitud; el estimado equivale a unos US$102.000.
A15: CIP automático del circuito de quesos | B15: 5000 | C15: US$ | D15: =B15*$B$6/1000000 -> 15.8523 | E15: =D15*(1+$B$8)*(1+$B$9) -> 23.699189 | F15: =320/3 -> 106.66667 | G15: Estimado con referencias | H15: Accio: sistemas CIP automáticos de US$4.000–10.000 (estaciones pequeñas) hasta US$80.000 (línea completa de leche). | I15: El estimado (un tercio de una estación de tres circuitos) está dentro del rango publicado.
A16: SCADA, historiador y MES ligero (licencias Ignition) | B16: 9500 | C16: US$ | D16: =B16*$B$6/1000000 -> 30.11937 | E16: =D16*(1+$B$8)*(1+$B$9) -> 45.028458 | F16: =BOM!$F$77 -> 130.79213 | G16: Valorado en el BOM | H16: Detalle ítem por ítem en la hoja BOM. | I16: Las licencias son una parte; el valor del modelo incluye servidor, red e instrumentación de la quesería.
A17: Controlador de las tinas (CompactLogix 1769-L33ER) | B17: 2200 | C17: US$ | D17: =B17*$B$6/1000000 -> 6.975012 | E17: =D17*(1+$B$8)*(1+$B$9) -> 10.427643 | F17: =E17 -> 10.427643 | G17: Precio publicado | H17: NJT Automation: 1769-L33ER nuevo, caja abierta, US$2.199,99. | I17: Componente incluido en la automatización de las tinas; se muestra como referencia del costo del control.
A18: Automatización de 2 tinas (liras con variador, sensor de coagulación, dosificación) | F18: =BOM!$F$73 -> 267.50965 | G18: Valorado en el BOM | H18: Detalle ítem por ítem en la hoja BOM.
A19: Tina del doble crema: medición y mando básicos | F19: =BOM!$F$74 -> 47.746861 | G19: Valorado en el BOM | H19: Detalle ítem por ítem en la hoja BOM.
A20: Medidor de grasa en línea (planta) | F20: =BOM!$F$76 -> 129.98093 | G20: Valorado en el BOM | H20: Detalle ítem por ítem en la hoja BOM.
A21: Enfriador de placas y tanque pulmón del suero | F21: 80 | G21: Estimado | H21: Pendiente de cotización.
A23: Siguiente paso: solicitud formal de cotización a proveedores en Colombia (equipos de proceso lácteo, instrumentación y control) para la hiladora, las tinas, el medidor de grasa, el CIP y la estación E18.

Sheet BOM
A1: BOM: lista de materiales del proyecto, del diseño técnico a la inversión
A2: Cada ítem sale del diseño técnico del proyecto (instrumentación de la sección 7 del README, modelo físico ISA-88, arquitectura ISA-95) y entra a la inversión de la hoja Quesería por su rubro. Lo especifica el paquete de la EDT indicado; el ingeniero de gestión y finanzas lo cotiza (paquete 6.1).
A4: Tasas y factores
A5: Concepto | C5: Valor | D5: Unidad | E5: Fuente
A6: Dólar | C6: =Cotizaciones!$B$6 -> 3170.46 | D6: $/US$ | E6: Hoja Cotizaciones.
A7: Euro | C7: =Cotizaciones!$B$7 -> 3569.9 | D7: $/€ | E7: Hoja Cotizaciones.
A8: Libra esterlina | C8: =C6*1.33 -> 4216.7118 | D8: $/£ | E8: Dólar × 1,33 US$/£ (estimado, octubre de 2026).
A9: Importación directa | C9: =Cotizaciones!$B$8 -> 0.3 | D9: % del precio | E9: Flete, seguro, arancel y aduana de un equipo que se trae del exterior; hoja Cotizaciones.
A10: Instalación | C10: =Cotizaciones!$B$9 -> 0.15 | D10: % del precio | E10: Montaje, cableado al PLC y pruebas; hoja Cotizaciones.
A11: Compra a un distribuidor en Colombia | C11: 0.15 | D11: % del precio | E11: Instrumentos, control y red comprados a distribuidores con stock local (Endress+Hauser, Rockwell, Siemens): el precio local suele ser el de lista más 10 a 20 %. Confirmar con su cotización.
A12: Lista de materiales
A13: Tag | B13: Descripción | C13: Etapa | D13: Rubro de la inversión | E13: Cantidad | F13: Precio unitario | G13: Moneda | H13: Origen (0 nacional, 1 importado, 2 distribuidor) | I13: Instalación (1 = sí) | J13: Valor ($ M) | K13: Parte de la quesería | L13: Paquete de la EDT | M13: Madurez (1 a 4) | N13: % imprevistos | O13: Fuente
A14: IR-01 | B14: Cámara termográfica para mantenimiento predictivo (FLIR E8 Pro) | C14: 0 | D14: Etapa 0: herramientas de mantenimiento y medición | E14: 1 | F14: 3299 | G14: US$ | H14: 2 | I14: 0 | J14: =E14*F14*$C$6/1000000*(1+(H14=1)*$C$9+(H14=2)*$C$11)*(1+I14*$C$10) -> 12.02825 | K14: =Quesería!$B$16 -> 0.36 | L14: 2.1 | M14: 2 | N14: =CHOOSE(M14,Quesería!$B$26,Quesería!$B$27,Quesería!$B$28,Quesería!$B$29) -> 0.1 | O14: FLIR, precio de lista 2026. | P14: D0
A15: VA-01 | B15: Analizador de vibraciones portátil | C15: 0 | D15: Etapa 0: herramientas de mantenimiento y medición | E15: 1 | F15: 1500 | G15: US$ | H15: 2 | I15: 0 | J15: =E15*F15*$C$6/1000000*(1+(H15=1)*$C$9+(H15=2)*$C$11)*(1+I15*$C$10) -> 5.4690435 | K15: =Quesería!$B$16 -> 0.36 | L15: 2.1 | M15: 4 | N15: =CHOOSE(M15,Quesería!$B$26,Quesería!$B$27,Quesería!$B$28,Quesería!$B$29) -> 0.25 | O15: Estimado. | P15: D0
A16: UL-01 | B16: Detector ultrasónico de fugas de aire y vapor | C16: 0 | D16: Etapa 0: herramientas de mantenimiento y medición | E16: 1 | F16: 1200 | G16: US$ | H16: 2 | I16: 0 | J16: =E16*F16*$C$6/1000000*(1+(H16=1)*$C$9+(H16=2)*$C$11)*(1+I16*$C$10) -> 4.3752348 | K16: =Quesería!$B$16 -> 0.36 | L16: 2.1 | M16: 4 | N16: =CHOOSE(M16,Quesería!$B$26,Quesería!$B$27,Quesería!$B$28,Quesería!$B$29) -> 0.25 | O16: Estimado. | P16: D0
A17: CMMS | B17: Software de mantenimiento (CMMS), suscripción del primer año | C17: 0 | D17: Etapa 0: herramientas de mantenimiento y medición | E17: 1 | F17: 6000000 | G17: $ | H17: 0 | I17: 0 | J17: =E17*F17*1/1000000*(1+(H17=1)*$C$9+(H17=2)*$C$11)*(1+I17*$C$10) -> 6 | K17: =Quesería!$B$16 -> 0.36 | L17: 2.1 | M17: 4 | N17: =CHOOSE(M17,Quesería!$B$26,Quesería!$B$27,Quesería!$B$28,Quesería!$B$29) -> 0.25 | O17: Estimado: unos $0,5 M al mes. | P17: D0
A18: BAL-02 | B18: Pesas patrón y calibración de las básculas de la planta | C18: 0 | D18: Etapa 0: herramientas de mantenimiento y medición | E18: 1 | F18: 4000000 | G18: $ | H18: 0 | I18: 0 | J18: =E18*F18*1/1000000*(1+(H18=1)*$C$9+(H18=2)*$C$11)*(1+I18*$C$10) -> 4 | K18: =Quesería!$B$16 -> 0.36 | L18: 2.3 | M18: 4 | N18: =CHOOSE(M18,Quesería!$B$26,Quesería!$B$27,Quesería!$B$28,Quesería!$B$29) -> 0.25 | O18: Estimado. | P18: D0
A19: MANT | B19: Repuestos y reparaciones urgentes que deje el diagnóstico (sellos, rodamientos, trampas de vapor) | C19: 0 | D19: Etapa 0: herramientas de mantenimiento y medición | E19: 1 | F19: 25000000 | G19: $ | H19: 0 | I19: 0 | J19: =E19*F19*1/1000000*(1+(H19=1)*$C$9+(H19=2)*$C$11)*(1+I19*$C$10) -> 25 | K19: =Quesería!$B$16 -> 0.36 | L19: 2.1 | M19: 4 | N19: =CHOOSE(M19,Quesería!$B$26,Quesería!$B$27,Quesería!$B$28,Quesería!$B$29) -> 0.25 | O19: Estimado del diagnóstico; se ajusta con el inventario de fallas. | P19: D0
A20: FT-301/303 | B20: Caudalímetro electromagnético sanitario DN50 (Promag H 100) | C20: 1 | D20: Tinas TQ-301 y TQ-303, control y tablero | E20: 2 | F20: 4816.4 | G20: US$ | H20: 2 | I20: 1 | J20: =E20*F20*$C$6/1000000*(1+(H20=1)*$C$9+(H20=2)*$C$11)*(1+I20*$C$10) -> 40.389688 | K20: 1 | L20: 3.1 | M20: 2 | N20: =CHOOSE(M20,Quesería!$B$26,Quesería!$B$27,Quesería!$B$28,Quesería!$B$29) -> 0.1 | O20: Instrumart, precio de lista (oct-2026). | P20: T13
A21: LT-301/303 | B21: Radar de nivel sanitario (Micropilot FMR43) | C21: 1 | D21: Tinas TQ-301 y TQ-303, control y tablero | E21: 2 | F21: 1936.25 | G21: US$ | H21: 2 | I21: 1 | J21: =E21*F21*$C$6/1000000*(1+(H21=1)*$C$9+(H21=2)*$C$11)*(1+I21*$C$10) -> 16.237134 | K21: 1 | L21: 3.1 | M21: 2 | N21: =CHOOSE(M21,Quesería!$B$26,Quesería!$B$27,Quesería!$B$28,Quesería!$B$29) -> 0.1 | O21: Instrumart, precio de lista. | P21: T13
A22: LSHH-301/303 | B22: Interruptor de nivel alto por vibración (Liquiphant FTL33) | C22: 1 | D22: Tinas TQ-301 y TQ-303, control y tablero | E22: 2 | F22: 436.59 | G22: US$ | H22: 2 | I22: 1 | J22: =E22*F22*$C$6/1000000*(1+(H22=1)*$C$9+(H22=2)*$C$11)*(1+I22*$C$10) -> 3.6611855 | K22: 1 | L22: 3.1 | M22: 2 | N22: =CHOOSE(M22,Quesería!$B$26,Quesería!$B$27,Quesería!$B$28,Quesería!$B$29) -> 0.1 | O22: Instrumart, precio de lista. | P22: T13
A23: TT-301/303 | B23: RTD sanitaria Pt100 con transmisor de 4–20 mA | C23: 1 | D23: Tinas TQ-301 y TQ-303, control y tablero | E23: 2 | F23: 480 | G23: US$ | H23: 2 | I23: 1 | J23: =E23*F23*$C$6/1000000*(1+(H23=1)*$C$9+(H23=2)*$C$11)*(1+I23*$C$10) -> 4.025216 | K23: 1 | L23: 3.1 | M23: 3 | N23: =CHOOSE(M23,Quesería!$B$26,Quesería!$B$27,Quesería!$B$28,Quesería!$B$29) -> 0.15 | O23: Intempco RS80, US$230,50 (Instrumart), más transmisor estimado en US$250. | P23: T13
A24: XV-301/303 | B24: Válvula de mariposa sanitaria DN50 con actuador neumático y posicionador on/off | C24: 1 | D24: Tinas TQ-301 y TQ-303, control y tablero | E24: 2 | F24: 1218.22 | G24: US$ | H24: 2 | I24: 1 | J24: =E24*F24*$C$6/1000000*(1+(H24=1)*$C$9+(H24=2)*$C$11)*(1+I24*$C$10) -> 10.215831 | K24: 1 | L24: 3.1 | M24: 2 | N24: =CHOOSE(M24,Quesería!$B$26,Quesería!$B$27,Quesería!$B$28,Quesería!$B$29) -> 0.1 | O24: Tameson, precio de lista. | P24: T13
A25: TV-301/303 | B25: Válvula de control del agua caliente y fría de la camisa | C25: 1 | D25: Tinas TQ-301 y TQ-303, control y tablero | E25: 2 | F25: 2500 | G25: US$ | H25: 2 | I25: 1 | J25: =E25*F25*$C$6/1000000*(1+(H25=1)*$C$9+(H25=2)*$C$11)*(1+I25*$C$10) -> 20.964667 | K25: 1 | L25: 3.1 | M25: 4 | N25: =CHOOSE(M25,Quesería!$B$26,Quesería!$B$27,Quesería!$B$28,Quesería!$B$29) -> 0.25 | O25: Estimado. | P25: T13
A26: SC-301/303 | B26: Variador de velocidad de las liras de corte y agitación (PowerFlex 525, 7,5 kW) | C26: 1 | D26: Tinas TQ-301 y TQ-303, control y tablero | E26: 2 | F26: 1850 | G26: US$ | H26: 2 | I26: 1 | J26: =E26*F26*$C$6/1000000*(1+(H26=1)*$C$9+(H26=2)*$C$11)*(1+I26*$C$10) -> 15.513853 | K26: 1 | L26: 3.1 | M26: 3 | N26: =CHOOSE(M26,Quesería!$B$26,Quesería!$B$27,Quesería!$B$28,Quesería!$B$29) -> 0.15 | O26: Estimado nuevo; NJT Automation lo publica usado en US$549,99. Las liras y sus motores ya existen. | P26: T13
A27: AT-301/303 | B27: Sensor de coagulación en línea (tipo CoAguLite) con su transmisor | C27: 1 | D27: Tinas TQ-301 y TQ-303, control y tablero | E27: 2 | F27: 6000 | G27: US$ | H27: 1 | I27: 1 | J27: =E27*F27*$C$6/1000000*(1+(H27=1)*$C$9+(H27=2)*$C$11)*(1+I27*$C$10) -> 56.878052 | K27: 1 | L27: 3.1 | M27: 4 | N27: =CHOOSE(M27,Quesería!$B$26,Quesería!$B$27,Quesería!$B$28,Quesería!$B$29) -> 0.25 | O27: Precio a solicitud; usa el PLC y el SCADA de la planta. Estimado. | P27: T13
A28: P-DOS | B28: Bombas dosificadoras de cuajo, cloruro de calcio y cultivo (ProMinent Gamma X) | C28: 1 | D28: Tinas TQ-301 y TQ-303, control y tablero | E28: 3 | F28: 1421 | G28: £ | H28: 2 | I28: 1 | J28: =E28*F28*$C$8/1000000*(1+(H28=1)*$C$9+(H28=2)*$C$11)*(1+I28*$C$10) -> 23.773052 | K28: 1 | L28: 3.1 | M28: 2 | N28: =CHOOSE(M28,Quesería!$B$26,Quesería!$B$27,Quesería!$B$28,Quesería!$B$29) -> 0.1 | O28: TF Pumps, precio de lista. | P28: T13
A29: XV-DOS | B29: Válvulas de destino de la dosificación a cada tina | C29: 1 | D29: Tinas TQ-301 y TQ-303, control y tablero | E29: 6 | F29: 300 | G29: US$ | H29: 2 | I29: 1 | J29: =E29*F29*$C$6/1000000*(1+(H29=1)*$C$9+(H29=2)*$C$11)*(1+I29*$C$10) -> 7.54728 | K29: 1 | L29: 3.1 | M29: 4 | N29: =CHOOSE(M29,Quesería!$B$26,Quesería!$B$27,Quesería!$B$28,Quesería!$B$29) -> 0.25 | O29: Estimado. | P29: T13
A30: BAL-01 | B30: Balanza de ingredientes con salida Ethernet | C30: 1 | D30: Tinas TQ-301 y TQ-303, control y tablero | E30: 1 | F30: 1500 | G30: US$ | H30: 2 | I30: 1 | J30: =E30*F30*$C$6/1000000*(1+(H30=1)*$C$9+(H30=2)*$C$11)*(1+I30*$C$10) -> 6.2894 | K30: 1 | L30: 3.1 | M30: 4 | N30: =CHOOSE(M30,Quesería!$B$26,Quesería!$B$27,Quesería!$B$28,Quesería!$B$29) -> 0.25 | O30: Estimado. | P30: T13
A31: pH-M01 | B31: pHmetro de mesa calibrado para la muestra de cuajada | C31: 1 | D31: Tinas TQ-301 y TQ-303, control y tablero | E31: 1 | F31: 1200 | G31: US$ | H31: 2 | I31: 0 | J31: =E31*F31*$C$6/1000000*(1+(H31=1)*$C$9+(H31=2)*$C$11)*(1+I31*$C$10) -> 4.3752348 | K31: 1 | L31: 3.1 | M31: 4 | N31: =CHOOSE(M31,Quesería!$B$26,Quesería!$B$27,Quesería!$B$28,Quesería!$B$29) -> 0.25 | O31: Estimado. | P31: T13
A32: PLC-300 | B32: Controlador CompactLogix 5380 (5069-L320ER) | C32: 1 | D32: Tinas TQ-301 y TQ-303, control y tablero | E32: 1 | F32: 2199.99 | G32: US$ | H32: 2 | I32: 1 | J32: =E32*F32*$C$6/1000000*(1+(H32=1)*$C$9+(H32=2)*$C$11)*(1+I32*$C$10) -> 9.2244114 | K32: 1 | L32: 3.2 | M32: 3 | N32: =CHOOSE(M32,Quesería!$B$26,Quesería!$B$27,Quesería!$B$28,Quesería!$B$29) -> 0.15 | O32: NJT Automation, reacondicionado; nuevo con el distribuidor. | P32: T13
A33: AI-300 | B33: Módulo de 8 entradas analógicas (5069-IF8) | C33: 1 | D33: Tinas TQ-301 y TQ-303, control y tablero | E33: 3 | F33: 449.99 | G33: US$ | H33: 2 | I33: 1 | J33: =E33*F33*$C$6/1000000*(1+(H33=1)*$C$9+(H33=2)*$C$11)*(1+I33*$C$10) -> 5.6603342 | K33: 1 | L33: 3.2 | M33: 3 | N33: =CHOOSE(M33,Quesería!$B$26,Quesería!$B$27,Quesería!$B$28,Quesería!$B$29) -> 0.15 | O33: NJT Automation. | P33: T13
A34: AO-300 | B34: Módulo de 4 salidas analógicas (5069-OF4) | C34: 1 | D34: Tinas TQ-301 y TQ-303, control y tablero | E34: 2 | F34: 600 | G34: US$ | H34: 2 | I34: 1 | J34: =E34*F34*$C$6/1000000*(1+(H34=1)*$C$9+(H34=2)*$C$11)*(1+I34*$C$10) -> 5.03152 | K34: 1 | L34: 3.2 | M34: 4 | N34: =CHOOSE(M34,Quesería!$B$26,Quesería!$B$27,Quesería!$B$28,Quesería!$B$29) -> 0.25 | O34: Estimado. | P34: T13
A35: DI-300 | B35: Módulo de 16 entradas digitales (5069-IB16) | C35: 1 | D35: Tinas TQ-301 y TQ-303, control y tablero | E35: 2 | F35: 419.99 | G35: US$ | H35: 2 | I35: 1 | J35: =E35*F35*$C$6/1000000*(1+(H35=1)*$C$9+(H35=2)*$C$11)*(1+I35*$C$10) -> 3.5219802 | K35: 1 | L35: 3.2 | M35: 2 | N35: =CHOOSE(M35,Quesería!$B$26,Quesería!$B$27,Quesería!$B$28,Quesería!$B$29) -> 0.1 | O35: NJT Automation, nuevo en caja abierta. | P35: T13
A36: DO-300 | B36: Módulo de 16 salidas digitales (5069-OB16) | C36: 1 | D36: Tinas TQ-301 y TQ-303, control y tablero | E36: 2 | F36: 450 | G36: US$ | H36: 2 | I36: 1 | J36: =E36*F36*$C$6/1000000*(1+(H36=1)*$C$9+(H36=2)*$C$11)*(1+I36*$C$10) -> 3.77364 | K36: 1 | L36: 3.2 | M36: 4 | N36: =CHOOSE(M36,Quesería!$B$26,Quesería!$B$27,Quesería!$B$28,Quesería!$B$29) -> 0.25 | O36: Estimado. | P36: T13
A37: PS-300 | B37: Distribuidor de potencia del bus (5069-FPD) y fuente de 24 V | C37: 1 | D37: Tinas TQ-301 y TQ-303, control y tablero | E37: 1 | F37: 400 | G37: US$ | H37: 2 | I37: 1 | J37: =E37*F37*$C$6/1000000*(1+(H37=1)*$C$9+(H37=2)*$C$11)*(1+I37*$C$10) -> 1.6771733 | K37: 1 | L37: 3.2 | M37: 4 | N37: =CHOOSE(M37,Quesería!$B$26,Quesería!$B$27,Quesería!$B$28,Quesería!$B$29) -> 0.25 | O37: Estimado. | P37: T13
A38: TC-300 | B38: Tablero de control en acero inoxidable: protecciones, borneras, cableado y canalización | C38: 1 | D38: Tinas TQ-301 y TQ-303, control y tablero | E38: 1 | F38: 25000000 | G38: $ | H38: 0 | I38: 1 | J38: =E38*F38*1/1000000*(1+(H38=1)*$C$9+(H38=2)*$C$11)*(1+I38*$C$10) -> 28.75 | K38: 1 | L38: 3.1 | M38: 4 | N38: =CHOOSE(M38,Quesería!$B$26,Quesería!$B$27,Quesería!$B$28,Quesería!$B$29) -> 0.25 | O38: Estimado de un tablerista nacional. | P38: T13
A39: FT-302 | B39: Caudalímetro electromagnético sanitario DN50 (Promag H 100) | C39: 1 | D39: Tina TQ-302 del doble crema | E39: 1 | F39: 4816.4 | G39: US$ | H39: 2 | I39: 1 | J39: =E39*F39*$C$6/1000000*(1+(H39=1)*$C$9+(H39=2)*$C$11)*(1+I39*$C$10) -> 20.194844 | K39: 1 | L39: 3.1 | M39: 2 | N39: =CHOOSE(M39,Quesería!$B$26,Quesería!$B$27,Quesería!$B$28,Quesería!$B$29) -> 0.1 | O39: Instrumart. | P39: T2
A40: LT-302 | B40: Radar de nivel sanitario (Micropilot FMR43) | C40: 1 | D40: Tina TQ-302 del doble crema | E40: 1 | F40: 1936.25 | G40: US$ | H40: 2 | I40: 1 | J40: =E40*F40*$C$6/1000000*(1+(H40=1)*$C$9+(H40=2)*$C$11)*(1+I40*$C$10) -> 8.1185672 | K40: 1 | L40: 3.1 | M40: 2 | N40: =CHOOSE(M40,Quesería!$B$26,Quesería!$B$27,Quesería!$B$28,Quesería!$B$29) -> 0.1 | O40: Instrumart. | P40: T2
A41: LSHH-302 | B41: Interruptor de nivel alto (Liquiphant FTL33) | C41: 1 | D41: Tina TQ-302 del doble crema | E41: 1 | F41: 436.59 | G41: US$ | H41: 2 | I41: 1 | J41: =E41*F41*$C$6/1000000*(1+(H41=1)*$C$9+(H41=2)*$C$11)*(1+I41*$C$10) -> 1.8305928 | K41: 1 | L41: 3.1 | M41: 2 | N41: =CHOOSE(M41,Quesería!$B$26,Quesería!$B$27,Quesería!$B$28,Quesería!$B$29) -> 0.1 | O41: Instrumart. | P41: T2
...

Sheet Escenarios
A1: Escenarios de la oferta
A2: La misma evaluación de la hoja Quesería con los supuestos que más mueven el resultado. La columna Oferta reproduce la hoja Quesería. Los flujos de cada escenario están agrupados debajo: se abren con el signo + de la izquierda.
A4: Qué cambia en cada escenario
A5: Supuesto | B5: Oferta | C5: Conservador | D5: Conservador con compuerta | E5: Sin arranque en 2027 | F5: Sin reubicación del personal | G5: Beneficios −20 % | H5: Beneficios +20 % | I5: Inversión +20 % | J5: Inversión −20 % | K5: Costos operativos +30 % | L5: Costos operativos −30 % | M5: Inflación del consenso | N5: Inflación persistente | O5: Salario mínimo 2027: 7 % | P5: Salario mínimo 2027: 10 % | Q5: Renta 30 % | R5: Crédito ordinario | S5: Garantía del FNG | T5: Sin crédito fiscal por innovación | U5: Sin las dos gestiones | V5: Adverso combinado | W5: Sin herramientas | X5: Con el costo de capital del proyecto | Y5: Solo etapas 0 y 1 | Z5: Sin el contrato de la cadena | AA5: Cadena sin pronto pago | AB5: Con la opción del suero a $45/kg | AC5: Enfriador del suero sin contrato | AD5: Opción del suero sin descuento ambiental
A6: Horas extra restantes que elimina la hiladora (1 = se cuentan) | B6: 1 | C6: 1 | D6: 1 | E6: 1 | F6: 1 | G6: 1 | H6: 1 | I6: 1 | J6: 1 | K6: 1 | L6: 1 | M6: 1 | N6: 1 | O6: 1 | P6: 1 | Q6: 1 | R6: 1 | S6: 1 | T6: 1 | U6: 1 | V6: 1 | W6: 1 | X6: 1 | Y6: 1 | Z6: 1 | AA6: 1 | AB6: 1 | AC6: 1 | AD6: 1
A7: Descuento ambiental del enfriador del suero (1 = se toma, si se compra) | B7: 1 | C7: 0 | D7: 0 | E7: 1 | F7: 1 | G7: 1 | H7: 1 | I7: 1 | J7: 1 | K7: 1 | L7: 1 | M7: 1 | N7: 1 | O7: 1 | P7: 1 | Q7: 1 | R7: 1 | S7: 1 | T7: 1 | U7: 1 | V7: 1 | W7: 1 | X7: 1 | Y7: 1 | Z7: 1 | AA7: 1 | AB7: 1 | AC7: 1 | AD7: 0
A8: Valor de los equipos al año 10 (1 = se cuenta) | B8: 1 | C8: 0 | D8: 0 | E8: 1 | F8: 1 | G8: 1 | H8: 1 | I8: 1 | J8: 1 | K8: 1 | L8: 1 | M8: 1 | N8: 1 | O8: 1 | P8: 1 | Q8: 1 | R8: 1 | S8: 1 | T8: 1 | U8: 1 | V8: 1 | W8: 1 | X8: 1 | Y8: 1 | Z8: 1 | AA8: 1 | AB8: 1 | AC8: 1 | AD8: 1
A9: Reubicación de los 2 operarios del hilado (1 = se cuenta) | B9: 1 | C9: 1 | D9: 1 | E9: 1 | F9: 0 | G9: 1 | H9: 1 | I9: 1 | J9: 1 | K9: 1 | L9: 1 | M9: 1 | N9: 1 | O9: 1 | P9: 1 | Q9: 1 | R9: 1 | S9: 1 | T9: 1 | U9: 1 | V9: 1 | W9: 1 | X9: 1 | Y9: 1 | Z9: 1 | AA9: 1 | AB9: 1 | AC9: 1 | AD9: 1
A10: Factor de beneficios | B10: 1 | C10: 1 | D10: 1 | E10: 1 | F10: 1 | G10: 0.8 | H10: 1.2 | I10: 1 | J10: 1 | K10: 1 | L10: 1 | M10: 1 | N10: 1 | O10: 1 | P10: 1 | Q10: 1 | R10: 1 | S10: 1 | T10: 1 | U10: 1 | V10: 0.8 | W10: 1 | X10: 1 | Y10: 1 | Z10: 1 | AA10: 1 | AB10: 1 | AC10: 1 | AD10: 1
A11: Factor de inversión | B11: 1 | C11: 1 | D11: 1 | E11: 1 | F11: 1 | G11: 1 | H11: 1 | I11: 1.2 | J11: 0.8 | K11: 1 | L11: 1 | M11: 1 | N11: 1 | O11: 1 | P11: 1 | Q11: 1 | R11: 1 | S11: 1 | T11: 1 | U11: 1 | V11: 1.2 | W11: 1 | X11: 1 | Y11: 1 | Z11: 1 | AA11: 1 | AB11: 1 | AC11: 1 | AD11: 1
A12: Factor de costos operativos nuevos | B12: 1 | C12: 1 | D12: 1 | E12: 1 | F12: 1 | G12: 1 | H12: 1 | I12: 1 | J12: 1 | K12: 1.3 | L12: 0.7 | M12: 1 | N12: 1 | O12: 1 | P12: 1 | Q12: 1 | R12: 1 | S12: 1 | T12: 1 | U12: 1 | V12: 1.3 | W12: 1 | X12: 1 | Y12: 1 | Z12: 1 | AA12: 1 | AB12: 1 | AC12: 1 | AD12: 1
A13: Garantía del crédito (0 = prenda sobre los equipos; 1 = FNG) | B13: =Quesería!$B$49 -> 0 | C13: 1 | D13: 1 | E13: =Quesería!$B$49 -> 0 | F13: =Quesería!$B$49 -> 0 | G13: =Quesería!$B$49 -> 0 | H13: =Quesería!$B$49 -> 0 | I13: =Quesería!$B$49 -> 0 | J13: =Quesería!$B$49 -> 0 | K13: =Quesería!$B$49 -> 0 | L13: =Quesería!$B$49 -> 0 | ... R13: =Quesería!$B$49 -> 0 | S13: 1 | T13: =Quesería!$B$49 -> 0 | U13: 1 | V13: =Quesería!$B$49 -> 0 | W13: 1 | X13: 1 | Y13: =Quesería!$B$49 -> 0 | Z13: =Quesería!$B$49 -> 0 | AA13: =Quesería!$B$49 -> 0 | AB13: =Quesería!$B$49 -> 0 | AC13: =Quesería!$B$49 -> 0 | AD13: =Quesería!$B$49 -> 0
A14: Tasa del crédito | B14: =Quesería!$B$45 -> 0.141 | C14: =Quesería!$B$45 -> 0.141 | D14: =Quesería!$B$45 -> 0.141 | E14: =Quesería!$B$45 -> 0.141 | F14: =Quesería!$B$45 -> 0.141 | G14: =Quesería!$B$45 -> 0.141 | H14: =Quesería!$B$45 -> 0.141 | I14: =Quesería!$B$45 -> 0.141 | ... Q14: =Quesería!$B$45 -> 0.141 | R14: 0.157 | S14: =Quesería!$B$45 -> 0.141 | T14: =Quesería!$B$45 -> 0.141 | U14: =Quesería!$B$45 -> 0.141 | V14: =Quesería!$B$45 -> 0.141 | W14: =Quesería!$B$45 -> 0.141 | X14: =Quesería!$B$45 -> 0.141 | Y14: =Quesería!$B$45 -> 0.141 | Z14: =Quesería!$B$45 -> 0.141 | ... AD14: =Quesería!$B$45 -> 0.141
A15: Ruta de inflación (1 base, 2 consenso, 3 persistente) | B15: =Quesería!$B$7 -> 1 | C15: =Quesería!$B$7 -> 1 | D15: =Quesería!$B$7 -> 1 | E15: =Quesería!$B$7 -> 1 | F15: =Quesería!$B$7 -> 1 | G15: =Quesería!$B$7 -> 1 | H15: =Quesería!$B$7 -> 1 | I15: =Quesería!$B$7 -> 1 | ... L15: =Quesería!$B$7 -> 1 | M15: 2 | N15: 3 | O15: =Quesería!$B$7 -> 1 | P15: =Quesería!$B$7 -> 1 | Q15: =Quesería!$B$7 -> 1 | R15: =Quesería!$B$7 -> 1 | S15: =Quesería!$B$7 -> 1 | T15: =Quesería!$B$7 -> 1 | U15: =Quesería!$B$7 -> 1 | V15: =Quesería!$B$7 -> 1 | ... AD15: =Quesería!$B$7 -> 1
A16: Incremento del salario mínimo de 2027 | B16: =Entorno!$B$12 -> 0.085 | C16: =Entorno!$B$12 -> 0.085 | D16: =Entorno!$B$12 -> 0.085 | E16: =Entorno!$B$12 -> 0.085 | F16: =Entorno!$B$12 -> 0.085 | G16: =Entorno!$B$12 -> 0.085 | H16: =Entorno!$B$12 -> 0.085 | I16: =Entorno!$B$12 -> 0.085 | ... N16: =Entorno!$B$12 -> 0.085 | O16: 0.07 | P16: 0.1 | Q16: =Entorno!$B$12 -> 0.085 | R16: =Entorno!$B$12 -> 0.085 | S16: =Entorno!$B$12 -> 0.085 | T16: =Entorno!$B$12 -> 0.085 | U16: =Entorno!$B$12 -> 0.085 | V16: =Entorno!$B$12 -> 0.085 | W16: =Entorno!$B$12 -> 0.085 | X16: =Entorno!$B$12 -> 0.085 | ... AD16: =Entorno!$B$12 -> 0.085
A17: Impuesto de renta | B17: =Quesería!$B$54 -> 0.35 | C17: =Quesería!$B$54 -> 0.35 | D17: =Quesería!$B$54 -> 0.35 | E17: =Quesería!$B$54 -> 0.35 | F17: =Quesería!$B$54 -> 0.35 | G17: =Quesería!$B$54 -> 0.35 | H17: =Quesería!$B$54 -> 0.35 | I17: =Quesería!$B$54 -> 0.35 | ... P17: =Quesería!$B$54 -> 0.35 | Q17: 0.3 | R17: =Quesería!$B$54 -> 0.35 | S17: =Quesería!$B$54 -> 0.35 | T17: =Quesería!$B$54 -> 0.35 | U17: =Quesería!$B$54 -> 0.35 | V17: =Quesería!$B$54 -> 0.35 | W17: =Quesería!$B$54 -> 0.35 | X17: =Quesería!$B$54 -> 0.35 | Y17: =Quesería!$B$54 -> 0.35 | ... AD17: =Quesería!$B$54 -> 0.35
A18: Costo de capital (1 = del proyecto; 0 = 16 % de la empresa) | B18: 1 | C18: 1 | D18: 1 | E18: 1 | F18: 1 | G18: 1 | H18: 1 | I18: 1 | J18: 1 | K18: 1 | L18: 1 | M18: 1 | N18: 1 | O18: 1 | P18: 1 | Q18: 1 | R18: 1 | S18: 1 | T18: 1 | U18: 1 | V18: 1 | W18: 0 | X18: 1 | Y18: 1 | Z18: 1 | AA18: 1 | AB18: 1 | AC18: 1 | AD18: 1
A19: Depreciación fiscal por tipo de activo (1 = sí; 0 = todo a 10 años) | B19: 1 | C19: 1 | D19: 1 | E19: 1 | F19: 1 | G19: 1 | H19: 1 | I19: 1 | J19: 1 | K19: 1 | L19: 1 | M19: 1 | N19: 1 | O19: 1 | P19: 1 | Q19: 1 | R19: 1 | S19: 1 | T19: 1 | U19: 1 | V19: 1 | W19: 0 | X19: 0 | Y19: 1 | Z19: 1 | AA19: 1 | AB19: 1 | AC19: 1 | AD19: 1
A20: Crédito fiscal por innovación, art. 256-1 (1 = se obtiene) | B20: =Quesería!$B$59 -> 1 | C20: 0 | D20: 0 | E20: =Quesería!$B$59 -> 1 | F20: =Quesería!$B$59 -> 1 | G20: =Quesería!$B$59 -> 1 | H20: =Quesería!$B$59 -> 1 | I20: =Quesería!$B$59 -> 1 | J20: =Quesería!$B$59 -> 1 | K20: =Quesería!$B$59 -> 1 | L20: =Quesería!$B$59 -> 1 | ... S20: =Quesería!$B$59 -> 1 | T20: 0 | U20: 0 | V20: =Quesería!$B$59 -> 1 | W20: 0 | X20: 0 | Y20: =Quesería!$B$59 -> 1 | Z20: =Quesería!$B$59 -> 1 | AA20: =Quesería!$B$59 -> 1 | AB20: =Quesería!$B$59 -> 1 | AC20: =Quesería!$B$59 -> 1 | AD20: =Quesería!$B$59 -> 1
A21: Etapa 2 (1 = se hace) | B21: 1 | C21: 1 | D21: 0 | E21: 1 | F21: 1 | G21: 1 | H21: 1 | I21: 1 | J21: 1 | K21: 1 | L21: 1 | M21: 1 | N21: 1 | O21: 1 | P21: 1 | Q21: 1 | R21: 1 | S21: 1 | T21: 1 | U21: 1 | V21: 1 | W21: 1 | X21: 1 | Y21: 0 | Z21: 1 | AA21: 1 | AB21: 1 | AC21: 1 | AD21: 1
A22: Beneficios según su respaldo (1 = caso conservador) | B22: 0 | C22: 1 | D22: 1 | E22: 0 | F22: 0 | G22: 0 | H22: 0 | I22: 0 | J22: 0 | K22: 0 | L22: 0 | M22: 0 | N22: 0 | O22: 0 | P22: 0 | Q22: 0 | R22: 0 | S22: 0 | T22: 0 | U22: 0 | V22: 0 | W22: 0 | X22: 0 | Y22: 0 | Z22: 0 | AA22: 0 | AB22: 0 | AC22: 0 | AD22: 0
A23: Arranque de la etapa 1 en 2027 (1 = se cuenta) | B23: 1 | C23: 1 | D23: 1 | E23: 0 | F23: 1 | G23: 1 | H23: 1 | I23: 1 | J23: 1 | K23: 1 | L23: 1 | M23: 1 | N23: 1 | O23: 1 | P23: 1 | Q23: 1 | R23: 1 | S23: 1 | T23: 1 | U23: 1 | V23: 1 | W23: 1 | X23: 1 | Y23: 1 | Z23: 1 | AA23: 1 | AB23: 1 | AC23: 1 | AD23: 1
A24: Contrato de marca propia con la cadena (1 = se firma) | B24: 1 | C24: 1 | D24: 1 | E24: 1 | F24: 1 | G24: 1 | H24: 1 | I24: 1 | J24: 1 | K24: 1 | L24: 1 | M24: 1 | N24: 1 | O24: 1 | P24: 1 | Q24: 1 | R24: 1 | S24: 1 | T24: 1 | U24: 1 | V24: 1 | W24: 1 | X24: 1 | Y24: 1 | Z24: 0 | AA24: 1 | AB24: 1 | AC24: 1 | AD24: 1
A25: Pronto pago de la cadena a 30 días (1 = se pacta) | B25: 1 | C25: 1 | D25: 1 | E25: 1 | F25: 1 | G25: 1 | H25: 1 | I25: 1 | J25: 1 | K25: 1 | L25: 1 | M25: 1 | N25: 1 | O25: 1 | P25: 1 | Q25: 1 | R25: 1 | S25: 1 | T25: 1 | U25: 1 | V25: 1 | W25: 1 | X25: 1 | Y25: 1 | Z25: 1 | AA25: 0 | AB25: 1 | AC25: 1 | AD25: 1
A26: Opción del suero: se compra el enfriador (1 = sí) | B26: 0 | C26: 0 | D26: 0 | E26: 0 | F26: 0 | G26: 0 | H26: 0 | I26: 0 | J26: 0 | K26: 0 | L26: 0 | M26: 0 | N26: 0 | O26: 0 | P26: 0 | Q26: 0 | R26: 0 | S26: 0 | T26: 0 | U26: 0 | V26: 0 | W26: 0 | X26: 0 | Y26: 0 | Z26: 0 | AA26: 0 | AB26: 1 | AC26: 1 | AD26: 1
A27: Contrato de venta del suero enfriado a $45/kg (1 = se firma) | B27: 1 | C27: 1 | D27: 1 | E27: 1 | F27: 1 | G27: 1 | H27: 1 | I27: 1 | J27: 1 | K27: 1 | L27: 1 | M27: 1 | N27: 1 | O27: 1 | P27: 1 | Q27: 1 | R27: 1 | S27: 1 | T27: 1 | U27: 1 | V27: 1 | W27: 1 | X27: 1 | Y27: 1 | Z27: 1 | AA27: 1 | AB27: 1 | AC27: 0 | AD27: 1
A28: Ajuste de las tasas nominales por la inflación de la ruta (Fisher) | B28: =CHOOSE(B$15,Entorno!$M$7,Entorno!$M$8,Entorno!$M$9)-CHOOSE(Quesería!$B$7,Entorno!$M$7,Entorno!$M$8,Entorno!$M$9) -> 0 | C28: =CHOOSE(C$15,Entorno!$M$7,Entorno!$M$8,Entorno!$M$9)-CHOOSE(Quesería!$B$7,Entorno!$M$7,Entorno!$M$8,Entorno!$M$9) -> 0 | D28: =CHOOSE(D$15,Entorno!$M$7,Entorno!$M$8,Entorno!$M$9)-CHOOSE(Quesería!$B$7,Entorno!$M$7,Entorno!$M$8,Entorno!$M$9) -> 0 | E28: =CHOOSE(E$15,Entorno!$M$7,Entorno!$M$8,Entorno!$M$9)-CHOOSE(Quesería!$B$7,Entorno!$M$7,Entorno!$M$8,Entorno!$M$9) -> 0 | F28: =CHOOSE(F$15,Entorno!$M$7,Entorno!$M$8,Entorno!$M$9)-CHOOSE(Quesería!$B$7,Entorno!$M$7,Entorno!$M$8,Entorno!$M$9) -> 0 | G28: =CHOOSE(G$15,Entorno!$M$7,Entorno!$M$8,Entorno!$M$9)-CHOOSE(Quesería!$B$7,Entorno!$M$7,Entorno!$M$8,Entorno!$M$9) -> 0 | H28: =CHOOSE(H$15,Entorno!$M$7,Entorno!$M$8,Entorno!$M$9)-CHOOSE(Quesería!$B$7,Entorno!$M$7,Entorno!$M$8,Entorno!$M$9) -> 0 | I28: =CHOOSE(I$15,Entorno!$M$7,Entorno!$M$8,Entorno!$M$9)-CHOOSE(Quesería!$B$7,Entorno!$M$7,Entorno!$M$8,Entorno!$M$9) -> 0 | ... AD28: =CHOOSE(AD$15,Entorno!$M$7,Entorno!$M$8,Entorno!$M$9)-CHOOSE(Quesería!$B$7,Entorno!$M$7,Entorno!$M$8,Entorno!$M$9) -> 0
A29: Costo de capital del proyecto | B29: =IF(B$18=1,Quesería!$B$44*(B$14+B$28+B$13*Quesería!$B$51*1.19)*(1-B$17)+(1-Quesería!$B$44)*(Quesería!$B$11+B$28),Quesería!$B$8+B$28) -> 0.1470725 | C29: =IF(C$18=1,Quesería!$B$44*(C$14+C$28+C$13*Quesería!$B$51*1.19)*(1-C$17)+(1-Quesería!$B$44)*(Quesería!$B$11+C$28),Quesería!$B$8+C$28) -> 0.15707772 | D29: =IF(D$18=1,Quesería!$B$44*(D$14+D$28+D$13*Quesería!$B$51*1.19)*(1-D$17)+(1-Quesería!$B$44)*(Quesería!$B$11+D$28),Quesería!$B$8+D$28) -> 0.15707772 | E29: =IF(E$18=1,Quesería!$B$44*(E$14+E$28+E$13*Quesería!$B$51*1.19)*(1-E$17)+(1-Quesería!$B$44)*(Quesería!$B$11+E$28),Quesería!$B$8+E$28) -> 0.1470725 | F29: =IF(F$18=1,Quesería!$B$44*(F$14+F$28+F$13*Quesería!$B$51*1.19)*(1-F$17)+(1-Quesería!$B$44)*(Quesería!$B$11+F$28),Quesería!$B$8+F$28) -> 0.1470725 | G29: =IF(G$18=1,Quesería!$B$44*(G$14+G$28+G$13*Quesería!$B$51*1.19)*(1-G$17)+(1-Quesería!$B$44)*(Quesería!$B$11+G$28),Quesería!$B$8+G$28) -> 0.1470725 | H29: =IF(H$18=1,Quesería!$B$44*(H$14+H$28+H$13*Quesería!$B$51*1.19)*(1-H$17)+(1-Quesería!$B$44)*(Quesería!$B$11+H$28),Quesería!$B$8+H$28) -> 0.1470725 | I29: =IF(I$18=1,Quesería!$B$44*(I$14+I$28+I$13*Quesería!$B$51*1.19)*(1-I$17)+(1-Quesería!$B$44)*(Quesería!$B$11+I$28),Quesería!$B$8+I$28) -> 0.1470725 | ... AD29: =IF(AD$18=1,Quesería!$B$44*(AD$14+AD$28+AD$13*Quesería!$B$51*1.19)*(1-AD$17)+(1-Quesería!$B$44)*(Quesería!$B$11+AD$28),Quesería!$B$8+AD$28) -> 0.1470725
A30: Conservador: cada beneficio según su respaldo (contratado y medido 100 %, técnicamente justificado 75 %, por medir 50 %, hipotético 0 %), sin descuento ambiental ni crédito fiscal, con garantía del FNG y sin valor final de los equipos. Conservador con compuerta: lo mismo, pero la etapa 2 no se hace porque sus condiciones no se cumplen. Las rutas de inflación mueven las tasas nominales en la misma proporción (Fisher). Crédito ordinario: 15,7 %, tasa de los créditos empresariales a medianas empresas a 3–5 años en la misma fuente. Garantía del FNG: si el banco no acepta la prenda. Sin crédito fiscal: si el CNBT no certifica la inversión. Renta 30 %: si prospera la reducción anunciada por el Gobierno. Adverso combinado: beneficios −20 %, inversión +20 % y costos +30 % a la vez. Los escenarios de herramientas se explican en la hoja Herramientas.
A32: Resultados por escenario
