Workbook

Sheet Portada
B2: Modelo financiero de la quesería
B3: Lácteos Fúquene · Oferta de IntegraMotion S.A.S.
B5: Documento
B6: Elaboró | C6: IntegraMotion S.A.S. · Producción y evaluación económica
B7: Curso | C7: Automatización de Procesos de Manufactura · 2026-2S · Universidad Nacional de Colombia
B8: Unidades | C8: Millones de pesos constantes de 2026, salvo donde se indique
B9: Estado de los chequeos | C9: =Chequeos!$C$29 -> OK
B10: Chequeos en OK | C10: =Chequeos!$B$29 -> 22 de 22
B12: Resultados de la oferta
B13: Costo de capital del proyecto | C13: =Quesería!B161 -> 0.139155 | D13: Crédito de fomento más garantía, después de impuestos, y capital propio al 25 %.
B14: TIR del proyecto en pesos corrientes | C14: =Quesería!B162 -> 0.21421387 | D14: Se compara con el costo de capital.
B15: TIR del proyecto en pesos constantes | C15: =Quesería!B163 -> 0.16467046 | D15: Se compara con la tasa real equivalente.
B16: Tasa real equivalente | C16: =Quesería!B164 -> 0.092019164 | D16: Costo de capital sin la inflación promedio de 2027 a 2037 (hoja Entorno).
B17: VPN a 10 años al costo de capital ($ M de 2026) | C17: =Quesería!B165 -> 367.41984 | D17: Valor que crea el proyecto después de pagar el capital.
B18: Recuperación simple (años) | C18: =Quesería!B166 -> 5.1086246 | D18: Años hasta recuperar la inversión con los flujos sin descontar.
B19: Recuperación descontada (años) | C19: =Quesería!B167 -> 6.9418802 | D19: Lo mismo, con los flujos descontados al costo de capital.
B20: TIR del inversionista en pesos corrientes | C20: =Quesería!B169 -> 0.41220926 | D20: Se compara con el 25 % que exige el socio.
B21: Cobertura mínima del servicio de la deuda | C21: =Quesería!B172 -> 1.2094267 | D21: Del proyecto solo; la empresa completa en la hoja Empresa.
B22: VPN si no se obtiene el crédito fiscal por innovación ($ M) | C22: =Escenarios!$T$33 -> 213.60067 | D22: La oferta incluye la gestión del crédito; sin la certificación el proyecto sigue creando valor.
B23: VPN si la primera compuerta no se supera: solo la etapa 0 ($ M) | C23: =Herramientas!B36 -> 84.568705 | D23: Con los ahorros conservadores supuestos. Sensibilidad en la hoja Herramientas.
B24: Deuda total / EBITDA más alta de la empresa | C24: =Empresa!$B$41 -> 1.2006412 | D24: Con el crédito del proyecto.
B25: Inversión total ($ M de 2026) | C25: =Quesería!$F$85 -> 1267.5137 | D25: Con imprevistos, sin IVA.
B26: Beneficio anual pleno ($ M de 2026) | C26: =Quesería!$E$111 -> 413.72349 | D26: A salarios de 2026; los ahorros de mano de obra crecen con el salario mínimo real.
B28: Contenido
B29: Quesería | C29: Supuestos, inversión, beneficios, flujo de caja, crédito y resultados de la oferta.
B30: Entorno | C30: Inflación y salario mínimo de 2027 a 2037 y lectura política y económica, con fuentes.
B31: Beneficios y costos | C31: Balance de masa de los quesos, cálculo de cada beneficio y costos operativos nuevos (energía, vapor y calibración).
B32: Cotizaciones | C32: Precios de referencia de los equipos y tasas de cambio.
B33: Escenarios | C33: La evaluación completa con los supuestos que más mueven el resultado.
B34: Riesgo | C34: Punto de equilibrio, gráfico de tornado, escenarios clave y respuesta a cada riesgo.
B35: Herramientas | C35: Herramientas económicas una sobre otra, valor de cada etapa y protecciones en los contratos.
B36: Empresa | C36: Efecto en el estado de resultados y el endeudamiento de Lácteos Fúquene.
B37: IntegraMotion | C37: Precio de los dos contratos, gastos de funcionamiento, entregables y plan de negocio.
B38: APU | C38: Análisis de precios unitarios de la ingeniería.
B39: Chequeos | C39: Diferencias que deben dar cero.
B41: Cómo se lee
B42: Texto azul | C42: Dato de entrada: se puede cambiar.
B43: Texto negro | C43: Fórmula: no se escribe encima.
B44: Fondo amarillo | C44: Cifra clave o supuesto que más mueve el resultado.

Sheet Quesería
A1: Modelo financiero de la quesería — Lácteos Fúquene
A2: Oferta de IntegraMotion S.A.S. Millones de pesos constantes de 2026. Texto azul: datos de entrada; negro: fórmulas; fondo amarillo: cifras clave.
A4: Supuestos
A5: Supuesto | B5: Valor | C5: Unidad | D5: Fuente o criterio
A6: Ruta de inflación (1 base, 2 consenso de los analistas, 3 persistente) | B6: 1 | C6: ruta | D6: Hoja Entorno: inflación de cada año de 2027 a 2037.
A7: Costo de capital de la empresa con su deuda actual | B7: 0.16 | C7: % | D7: 70 % deuda al 18 % (intereses / deuda de 2026: 252 / 1.400) y 30 % capital propio al 25 %. Es la referencia de la primera entrega.
A8: Costo de capital del proyecto en pesos corrientes | B8: =$B$40*($B$41+$B$48*$B$44*1.19)*(1-$B$10)+(1-$B$40)*$B$46 -> 0.139155 | C8: % | D8: Con la deuda que de verdad financia el proyecto: crédito de fomento más la comisión de la garantía, después de impuestos (70 %), y capital propio al 25 % (30 %). Con él se descuentan los flujos.
A9: Tasa real equivalente | B9: =(1+$B$8)/(1+CHOOSE($B$6,Entorno!$M$7,Entorno!$M$8,Entorno!$M$9))-1 -> 0.092019164 | C9: % | D9: El costo de capital sin la inflación promedio de la ruta; con ella se compara la TIR en pesos constantes.
A10: Impuesto de renta | B10: 0.35 | C10: % | D10: Tarifa general de personas jurídicas.
A11: Vida fiscal de maquinaria y equipo | B11: 10 | C11: años | D11: Línea recta, 10 % anual (art. 137 ET). La de cada rubro está en la tabla de inversión.
A12: Beneficio del primer año de cada etapa | B12: 0.75 | C12: % del pleno | D12: Arranque, ajuste de recetas y formación.
A13: Meses de operación de la etapa 1 en 2027 | B13: 4 | C13: meses | D13: El contrato 1 dura 4 meses: la etapa 1 arranca a mitad de 2027. Se cuentan 4 meses con el beneficio de arranque; la compuerta de diciembre usa esos datos medidos.
A14: Costo de reemplazar a un operario con alguien de afuera | B14: 0.3 | C14: % del costo anual | D14: Reclutamiento, vacante y curva de aprendizaje: 30 a 50 % del salario anual (Semana, febrero de 2026). Se evita al cubrir las vacantes con personal ya formado.
A15: Parte del contrato 1 que es diagnóstico, medidas organizacionales y gestión | B15: =2/6 -> 0.33333333 | C15: % | D15: Dos de los seis integrantes (procesos y finanzas). Se deduce como gasto y su IVA va en la declaración de IVA.
A16: Caso conservador: beneficio contratado | B16: 1 | C16: % del beneficio | D16: Respaldo 1. El suero: el contrato firmado es condición de la compuerta.
A17: Caso conservador: beneficio medido en la planta | B17: 1 | C17: % del beneficio | D17: Respaldo 2. Medido en la etapa 0 con el protocolo de medida y verificación.
A18: Caso conservador: beneficio técnicamente justificado | B18: 0.75 | C18: % del beneficio | D18: Respaldo 3. Balance de masa, VSM, literatura o datos de la planta.
A19: Caso conservador: beneficio por medir en la etapa 0 | B19: 0.5 | C19: % del beneficio | D19: Respaldo 4. Supuesto razonable que todavía no tiene medición.
A20: Caso conservador: beneficio hipotético | B20: 0 | C20: % del beneficio | D20: Respaldo 5.
A21: Mantenimiento de equipos nuevos | B21: 0.03 | C21: % equipos/año | D21: Práctica de la industria para equipos de proceso.
A22: Suscripciones de software del SCADA de la quesería | B22: 12 | C22: $ M/año | D22: Licencias de SCADA, historiador y analítica dimensionadas para una línea.
A23: Días de cartera sobre las ventas adicionales | B23: 30 | C23: días | D23: Política comercial de la planta. El capital de trabajo suma cartera e inventario al costo y resta las cuentas por pagar; se recupera al final del horizonte.
A24: Días de inventario del queso adicional | B24: 5 | C24: días | D24: Queso fresco: se despacha en la semana. Se valora al costo, no al precio.
A25: Costo de ventas sobre ventas | B25: 0.82 | C25: % | D25: Estado de resultados del caso: leche, insumos, nómina, energía y mantenimiento sobre las ventas.
A26: Días de cuentas por pagar sobre los costos operativos nuevos | B26: 22 | C26: días | D26: Balance del caso: cuentas por pagar de 1.206 sobre compras de leche e insumos.
A27: Leche de la quesería | B27: 9000 | C27: L/día | D27: Reparto de la leche de la planta.
A28: Leche de la planta | B28: 25000 | C28: L/día | D28: Caso de estudio.
A29: Parte de la quesería en la leche | B29: =$B$27/$B$28 -> 0.36 | C29: % | D29: Reparte la grasa en línea, el mantenimiento y la etapa 0.
A30: Ventas de la quesería | B30: 6772 | C30: $ M/año | D30: Caso de estudio (294 días de operación).
A31: Ventas de la planta | B31: 30457 | C31: $ M/año | D31: Caso de estudio.
A32: Parte de la quesería en las ventas | B32: =$B$30/$B$31 -> 0.22234626 | C32: % | D32: Reparte la reducción de merma.
A33: Costo anual de un operario | B33: 36 | C33: $ M/año | D33: Salario, prestaciones y aportes.
A34: Meses de traslape mientras se forman los operarios de la hiladora | B34: 3 | C34: meses | D34: Los 2 operarios que pasan a cubrir vacantes siguen en el hilado hasta que la hiladora opera sola; esas vacantes se cubren mientras tanto.
A35: Descuento tributario por inversión ambiental (art. 255 ET) | B35: 0.25 | C35: % inversión | D35: Sobre el enfriador y el tanque del suero, que dejan de verterlo. Requiere certificado de la CAR; IntegraMotion lo tramita.
A36: IVA de equipos y contratos de integración | B36: 0.19 | C36: % | D36: Se paga al comprar y se recupera como descuento en la declaración de renta del año, que se presenta al año siguiente (art. 258-1 ET: activos fijos productivos y servicios para ponerlos en uso). El IVA del diagnóstico y del aval se descuenta en la declaración de IVA. Los valores de la inversión van sin IVA.
A37: Reposición del hardware del SCADA en el año 5 | B37: 0.4 | C37: % del rubro SCADA | D37: Servidor, red y estaciones (vida fiscal de 5 años); las licencias siguen en las suscripciones.
A38: Reposición parcial de instrumentación en el año 6 | B38: 0.1 | C38: % de los equipos de la etapa 1 | D38: Sensores, celdas de carga y sondas en ambiente húmedo y con lavados.
A39: Valor de los equipos al año 10 | B39: 0.1 | C39: % de su costo | D39: Se vende o se toma como parte de pago; se grava completo.
A40: Parte de la inversión financiada con crédito | B40: 0.7 | C40: % | D40: Líneas Bancóldex Impulso a la Productividad y Transformación Digital, a través del banco de la empresa.
A41: Tasa del crédito de fomento (efectiva anual, pesos corrientes) | B41: 0.141 | C41: % | D41: Superfinanciera, datos abiertos: créditos con recursos de redescuento a medianas empresas, 3 a 5 años, mayo a julio de 2026. El crédito se pacta en pesos corrientes; cada pago se pasa a pesos constantes con el factor del flujo.
...

Sheet Entorno
A1: Entorno económico y político del proyecto
A2: La quesería se ejecuta en 2027 y 2028 y opera hasta 2037. Precios en pesos de 2026; esta hoja dice cuánto cambian año por año la inflación y el salario mínimo.
A4: Inflación y salario mínimo, año por año
B5: Año 0 | C5: Año 1 | D5: Año 2 | E5: Año 3 | F5: Año 4 | G5: Año 5 | H5: Año 6 | I5: Año 7 | J5: Año 8 | K5: Año 9 | L5: Año 10 | M5: Promedio
A6: Año calendario | B6: 2027 | C6: 2028 | D6: 2029 | E6: 2030 | F6: 2031 | G6: 2032 | H6: 2033 | I6: 2034 | J6: 2035 | K6: 2036 | L6: 2037
A7: Ruta 1 · base: inflación de cada año | B7: 0.06 | C7: 0.05 | D7: 0.045 | E7: 0.04 | F7: 0.04 | G7: 0.04 | H7: 0.04 | I7: 0.04 | J7: 0.04 | K7: 0.04 | L7: 0.04 | M7: =EXP(SUMPRODUCT(LN(1+B7:L7))/11)-1 -> 0.043163928
A8: Ruta 2 · consenso de los analistas | B8: 0.059 | C8: 0.045 | D8: 0.037 | E8: 0.034 | F8: 0.034 | G8: 0.034 | H8: 0.034 | I8: 0.034 | J8: 0.034 | K8: 0.034 | L8: 0.034 | M8: =EXP(SUMPRODUCT(LN(1+B8:L8))/11)-1 -> 0.037518712
A9: Ruta 3 · inflación persistente | B9: 0.065 | C9: 0.065 | D9: 0.065 | E9: 0.065 | F9: 0.065 | G9: 0.065 | H9: 0.065 | I9: 0.065 | J9: 0.065 | K9: 0.065 | L9: 0.065 | M9: =EXP(SUMPRODUCT(LN(1+B9:L9))/11)-1 -> 0.065
A10: Promedio geométrico de 2027 a 2037. La ruta que usa el modelo se elige en los supuestos de la hoja Quesería.
A12: Incremento del salario mínimo para 2027 | B12: 0.085 | D12: Davivienda: inflación de 2026 (6,91 %) − productividad (0,32 %) + «sorpresa política» (1,91 %). Gremios: 8 % a 9,5 %; Credicorp: 9 % a 10 %.
A13: Aumento real del salario mínimo desde 2028 | B13: 0.005 | D13: El Gobierno plantea volver a ajustarlo por inflación y productividad; la productividad del trabajo ha estado cerca de cero.
A14: Salario mínimo real de 2027 con la ruta base (2026 = 1) | B14: =(1+B12)/(1+B7) -> 1.0235849 | D14: Cuánto sube por encima de la inflación.
A15: Salario mínimo real de 2028 con la ruta base (2026 = 1) | B15: =B14*(1+B13) -> 1.0287028 | D15: Reajusta los contratos de IntegraMotion: la etapa 2 se ejecuta en 2028.
A16: Salario mínimo de 2027 en pesos | B16: =1750905*(1+B12) -> 1899731.9 | D16: Decreto de 2026: $1.750.905.
A17: Afecta lo que depende del salario: horas extra y relevo de operarios (beneficios), traslape del personal y honorarios de IntegraMotion.
A19: Cómo se armaron las rutas
A20: • Encuesta de analistas del Banco de la República (septiembre de 2026): 6,8 % al cierre de 2026, 5,1 % al cierre de 2027, 4,0 % en agosto de 2028 y 3,4 % a cinco años. Los analistas han subido su pronóstico casi todos los meses de 2026.
A21: • Inflación de septiembre de 2026: 6,29 % anual (DANE), la más alta desde julio de 2024. Tasa del Banco de la República: 12,25 % desde el 1 de octubre, con una subida de 25 puntos básicos y la junta dividida.
A22: • Rutas en promedio de cada año. Consenso: de 6,8 % en diciembre de 2026 a 5,1 % en diciembre de 2027 da 5,9 % para 2027; luego 4,5 %, 3,7 % y 3,4 %. Ruta base: por encima del consenso cada año, con más margen desde 2028, y 4 % desde 2030, el techo del rango de la meta (2 % a 4 %). Ruta persistente: la inflación se queda cerca del dato de septiembre todo el horizonte.
A24: Lectura política y económica (octubre de 2026)
A25: • Salario mínimo: en 2026 subió 23,7 %, muy por encima de la inflación. El Gobierno de Abelardo de la Espriella y su ministro de Hacienda piden volver a un ajuste técnico (inflación más productividad); los analistas esperan 8 % a 10 % para 2027 por una prima política. La decisión se toma a más tardar el 30 de diciembre.
A26: • Presupuesto General de 2027: el Congreso lo aprobó el 20 de octubre por $634,9 billones, pero quedó en vilo por un presunto vicio de trámite en el artículo 65 (Senado y Cámara habrían aprobado textos distintos); si se confirma, el Gobierno lo expide por decreto. Suma incertidumbre fiscal: hace menos probable que las tasas de interés bajen rápido.
A27: • Política monetaria: el Banco de la República volvió a subir la tasa en septiembre. Davivienda espera bajadas graduales hasta 11 % al cierre de 2027. El crédito de fomento se pacta sobre la IBR más un margen, así que sigue esa tendencia.
A28: • Impuestos: el Gobierno anunció una reforma para bajar la carga de las empresas, sin tarifa definida todavía. El modelo deja la renta en 35 % y prueba 30 % en la hoja Escenarios.
A29: • Energía: el gas para la industria depende cada vez más de importaciones y El Niño presiona las tarifas. La hoja Escenarios prueba costos operativos 30 % más altos.
A31: Cómo entra al modelo
... A43: • Presupuesto de 2027 aprobado y en vilo: portafolio.co/economia/gobierno/presupuesto-de-2027-recien-aprobado-en-vilo-por-inminente-hundimiento-por-vicio-de-tramite-en-el-congreso-504829

Sheet Beneficios y costos
A1: Beneficios y costos operativos de la quesería
A2: Cada beneficio sale del balance de masa, de los precios y de la mejora que se espera; cada costo nuevo, del consumo de los equipos. $ M constantes de 2026. Las cifras en azul se miden en la etapa 0.
A4: Datos de la operación
A5: Dato | B5: Valor | C5: Unidad | D5: Fuente o criterio
A6: Días de operación al año | B6: 294 | C6: días | D6: Caso: lunes a sábado menos festivos.
A7: Densidad de la leche | B7: 1.03 | C7: kg/L | D7: Valor típico.
A8: Grasa de la leche cruda | B8: 0.036 | C8: % m/m | D8: Hato Holstein de la sabana de Ubaté.
A9: Grasa de la crema | B9: 0.4 | C9: % m/m | D9: Descremadora centrífuga.
A10: Grasa de más que se deja hoy al estandarizar a mano | B10: 0.0008 | C10: puntos | D10: Cuadro de Pearson y muestreo: el operario deja margen para no quedar por debajo del mínimo.
A11: Grasa de más con el medidor en línea | B11: 0.0003 | C11: puntos | D11: Medidor de grasa y densidad con válvula de remezcla.
A12: Crema añadida al fundido del doble crema | B12: 30 | C12: kg/día | D12: Sale de la crema de la estandarización.
A13: Agua de lavado del grano del campesino | B13: 0.03 | C13: kg/kg leche | D13: Sale con el suero.
A14: Queso adicional por el corte con sensor de coagulación | B14: 0.0015 | C14: kg/kg leche | D14: Menos finos al suero en el campesino y la mozzarella (0,15 puntos de rendimiento).
A15: Queso adicional con la hiladora-moldeadora | B15: 0.02 | C15: % del queso hilado | D15: Menos grasa y finos al agua de hilado que en la marmita a mano.
A16: Sobrepeso de los quesos hoy | B16: 0.01 | C16: % del peso | D16: Igual al de las bolsas UHT del caso.
A17: Sobrepeso con la controladora de peso | B17: 0.005 | C17: % del peso | D17: La controladora rechaza y ajusta el corte.
... A24: Ahorro con limpieza CIP automática | B24: 0.1 | C24: % de ese gasto | D24: Recuperación de soluciones y ciclos medidos en lugar de lavado a mano.
A25: Parte del circuito de quesos en la limpieza | B25: =1/3 -> 0.33333333 | C25: % | D25: Uno de los tres circuitos (quesos, yogur y UHT).
A26: Horas extra diarias del hilado que se evitan en cada etapa | B26: 0.5 | C26: h/día | D26: VSM: el hilado a mano necesita 8,4 h en una ventana de 7,4 h.
A27: Operarios del hilado | B27: 4 | C27: personas | D27: Dos parejas.
A28: Costo de la hora extra | B28: 20000 | C28: $/h | D28: Costo de la hora de un salario mínimo más el recargo de 25 %.
A29: Precio de la crema vendida | B29: 9000 | C29: $/kg | D29: Crema al 40 % a granel.
A30: Precio de la leche entera UHT | B30: 3100 | C30: $/L | D30: Precio a distribuidor del caso.
A31: Precio del suero hoy, sin enfriar | B31: 30 | C31: $/kg | D31: Caso de estudio.
A32: Precio del suero enfriado con contrato | B32: 45 | C32: $/kg | D32: Contrato anual con una fábrica de alimento balanceado; se valida en la etapa 0 con dos cotizaciones.
A33: Operarios que libera la hiladora y cubren vacantes | B33: 2 | C33: personas | D33: Nadie sale de la empresa: cubren vacantes que la planta tendría que contratar.
A35: Quesos
A36: Referencia | B36: Leche (L/día) | C36: Grasa objetivo | D36: Rendimiento (kg/kg) | E36: Precio ($/kg) | F36: Insumos y empaque ($/kg)
A37: Q1 campesino | B37: 4500 | C37: 0.026 | D37: 0.12 | E37: 19500 | F37: 750
A38: Q2 doble crema (leche entera, sin estandarizar) | B38: 3000 | C38: =$B$8 -> 0.036 | D38: 0.13 | E38: 22000 | F38: 900
A39: Q3 mozzarella | B39: 1500 | C39: 0.026 | D39: 0.1 | E39: 24000 | F39: 800
A40: Rendimiento del campesino y la mozzarella sobre leche estandarizada; el del doble crema, sobre leche entera e incluye la crema del fundido. Precios: Corabastos y mercado mayorista, 2026.
A42: Estandarización de grasa de toda la recepción (kg/día)
A43: Referencia | B43: Leche (L/día) | C43: Grasa objetivo | D43: Crema retirada hoy | E43: Crema con medidor | F43: Crema adicional
A44: L1 leche entera UHT | B44: 6500 | C44: 0.03 | D44: =MAX(0,B44*$B$7*($B$8-(C44+$B$10))/($B$9-(C44+$B$10))) -> 94.295775 | E44: =MAX(0,B44*$B$7*($B$8-(C44+$B$11))/($B$9-(C44+$B$11))) -> 103.22288 | F44: =E44-D44 -> 8.9271088
A45: L2 deslactosada | B45: 3500 | C45: 0.015 | D45: =MAX(0,B45*$B$7*($B$8-(C45+$B$10))/($B$9-(C45+$B$10))) -> 189.5393 | E45: =MAX(0,B45*$B$7*($B$8-(C45+$B$11))/($B$9-(C45+$B$11))) -> 193.97842 | F45: =E45-D45 -> 4.4391223
A46: L3 bebida láctea | B46: 2000 | C46: 0.02 | D46: =MAX(0,B46*$B$7*($B$8-(C46+$B$10))/($B$9-(C46+$B$10))) -> 82.57384 | E46: =MAX(0,B46*$B$7*($B$8-(C46+$B$11))/($B$9-(C46+$B$11))) -> 85.177772 | F46: =E46-D46 -> 2.6039323
A47: Q1 campesino | B47: =B37 -> 4500 | C47: =C37 -> 0.026 | D47: =MAX(0,B47*$B$7*($B$8-(C47+$B$10))/($B$9-(C47+$B$10))) -> 114.26045 | E47: =MAX(0,B47*$B$7*($B$8-(C47+$B$11))/($B$9-(C47+$B$11))) -> 120.30907 | F47: =E47-D47 -> 6.0486213
A48: Q3 mozzarella | B48: =B39 -> 1500 | C48: =C39 -> 0.026 | D48: =MAX(0,B48*$B$7*($B$8-(C48+$B$10))/($B$9-(C48+$B$10))) -> 38.086817 | E48: =MAX(0,B48*$B$7*($B$8-(C48+$B$11))/($B$9-(C48+$B$11))) -> 40.103024 | F48: =E48-D48 -> 2.0162071
A49: Y1 yogur natural | B49: 1400 | C49: 0.03 | D49: =MAX(0,B49*$B$7*($B$8-(C49+$B$10))/($B$9-(C49+$B$10))) -> 20.309859 | E49: =MAX(0,B49*$B$7*($B$8-(C49+$B$11))/($B$9-(C49+$B$11))) -> 22.232621 | F49: =E49-D49 -> 1.9227619
...

Sheet Cotizaciones
A1: Cotizaciones y precios de referencia de los equipos
A2: Precios publicados en octubre de 2026, convertidos a pesos con la TRM y el euro del día. Sin cotización formal todavía: las cifras en azul se reemplazan cuando lleguen las de los proveedores.
A4: Tasas de cambio y factores
A5: Concepto | B5: Valor | C5: Unidad | D5: Fuente
A6: Tasa representativa del mercado (16 de octubre de 2026) | B6: 3170.46 | C6: $/US$ | D6: Superintendencia Financiera, citada por Noticias Caracol, 16-oct-2026.
A7: Euro en pesos (15 de octubre de 2026) | B7: 3569.9 | C7: $/€ | D7: Investing.com, citado por Portafolio, 15-oct-2026.
A8: Flete, seguro, arancel y nacionalización de un equipo importado | B8: 0.3 | C8: % del precio | D8: Supuesto: flete marítimo e internación desde Asia o Europa; confirmar con el agente de aduanas.
A9: Instalación, integración y puesta en marcha | B9: 0.15 | C9: % del precio | D9: Supuesto: montaje, cableado al PLC y pruebas en sitio.
A11: Equipos de la inversión
A12: Equipo | B12: Precio de referencia | C12: Moneda | D12: Precio en $ M | E12: Con nacionalización e instalación ($ M) | F12: Valor en el modelo ($ M) | G12: Estado | H12: Referencia | I12: Lectura
A13: Controladora de peso y detector de metales (estación E18) | B13: 7000 | C13: US$ | D13: =B13*$B$6/1000000 -> 22.19322 | E13: =D13*(1+$B$8)*(1+$B$9) -> 33.178864 | F13: =E13 -> 33.178864 | G13: Precio publicado | H13: Made-in-China, catálogo de controladoras de peso: equipo combinado con detector de metales, US$6.500–7.000 por unidad (oct-2026). | I13: Equipo de origen chino. Una marca europea puede costar 3 a 4 veces más; se recomienda pedir las dos cotizaciones.
A14: Hiladora-moldeadora continua de 300 kg/h | B14: 39000 | C14: € | D14: =B14*$B$7/1000000 -> 139.2261 | E14: =D14*(1+$B$8)*(1+$B$9) -> 208.14302 | F14: 322.6 | G14: Estimado con referencias | H14: Werktuigen: DIMA 100 Compact usada (2023), 100 kg/h, €39.000. Ullmer's: cocedora-hiladora DIMA usada, US$35.000. Made-in-China: cocedora-hiladora por lotes, US$12.500–18.500. | I14: Las referencias son de máquinas usadas de 100 kg/h o de equipos por lotes. Una continua nueva de 300 kg/h (Milkylab, CMT, Dima) es de precio a solicitud; el estimado equivale a unos US$102.000.
A15: CIP automático del circuito de quesos | B15: 5000 | C15: US$ | D15: =B15*$B$6/1000000 -> 15.8523 | E15: =D15*(1+$B$8)*(1+$B$9) -> 23.699189 | F15: =320/3 -> 106.66667 | G15: Estimado con referencias | H15: Accio: sistemas CIP automáticos de US$4.000–10.000 (estaciones pequeñas) hasta US$80.000 (línea completa de leche). | I15: El estimado (un tercio de una estación de tres circuitos) está dentro del rango publicado.
A16: SCADA, historiador y MES ligero (licencias Ignition) | B16: 9500 | C16: US$ | D16: =B16*$B$6/1000000 -> 30.11937 | E16: =D16*(1+$B$8)*(1+$B$9) -> 45.028458 | F16: =200/3 -> 66.666667 | G16: Estimado con referencias | H16: Industrial Monitor Direct (jul-2026): Ignition Vision ilimitado US$6.500; paquete «The Works» US$9.500. | I16: Las licencias son una parte; el valor del modelo incluye servidor, red e instrumentación de la quesería.
A17: Controlador de las tinas (CompactLogix 1769-L33ER) | B17: 2200 | C17: US$ | D17: =B17*$B$6/1000000 -> 6.975012 | E17: =D17*(1+$B$8)*(1+$B$9) -> 10.427643 | F17: =E17 -> 10.427643 | G17: Precio publicado | H17: NJT Automation: 1769-L33ER nuevo, caja abierta, US$2.199,99. | I17: Componente incluido en la automatización de las tinas; se muestra como referencia del costo del control.
A18: Automatización de 2 tinas (liras con variador, sensor de coagulación, dosificación) | F18: 180 | G18: Estimado | H18: Pendiente: sensor de coagulación y liras motorizadas son de precio a solicitud.
A19: Tina del doble crema: medición y mando básicos | F19: 30 | G19: Estimado | H19: Pendiente de cotización.
A20: Medidor de grasa en línea (planta) | F20: 120 | G20: Estimado | H20: FOSS, Anton Paar y Maselli: precio a solicitud.
A21: Enfriador de placas y tanque pulmón del suero | F21: 80 | G21: Estimado | H21: Pendiente de cotización.
A23: Siguiente paso: solicitud formal de cotización a proveedores en Colombia (equipos de proceso lácteo, instrumentación y control) para la hiladora, las tinas, el medidor de grasa, el CIP y la estación E18.

Sheet Escenarios
A1: Escenarios de la oferta
A2: La misma evaluación de la hoja Quesería con los supuestos que más mueven el resultado. La columna Oferta reproduce la hoja Quesería.
A4: Qué cambia en cada escenario
A5: Supuesto | B5: Oferta | C5: Conservador | D5: Conservador con compuerta | E5: Sin arranque en 2027 | F5: Sin relevo natural | G5: Beneficios −20 % | H5: Beneficios +20 % | I5: Inversión +20 % | J5: Inversión −20 % | K5: Costos operativos +30 % | L5: Costos operativos −30 % | M5: Inflación del consenso | N5: Inflación persistente | O5: Salario mínimo 2027: 7 % | P5: Salario mínimo 2027: 10 % | Q5: Renta 30 % | R5: Crédito ordinario | S5: Garantía del FNG | T5: Sin crédito fiscal por innovación | U5: Sin las dos gestiones | V5: Adverso combinado | W5: Sin herramientas | X5: Con el costo de capital del proyecto | Y5: Solo etapas 0 y 1
A6: Horas extra restantes que elimina la hiladora (1 = se cuentan) | B6: 1 | C6: 1 | D6: 1 | E6: 1 | F6: 1 | G6: 1 | H6: 1 | I6: 1 | J6: 1 | K6: 1 | L6: 1 | M6: 1 | N6: 1 | O6: 1 | P6: 1 | Q6: 1 | R6: 1 | S6: 1 | T6: 1 | U6: 1 | V6: 1 | W6: 1 | X6: 1 | Y6: 1
A7: Descuento tributario del suero (1 = se toma) | B7: 1 | C7: 0 | D7: 0 | E7: 1 | F7: 1 | G7: 1 | H7: 1 | I7: 1 | J7: 1 | K7: 1 | L7: 1 | M7: 1 | N7: 1 | O7: 1 | P7: 1 | Q7: 1 | R7: 1 | S7: 1 | T7: 1 | U7: 1 | V7: 1 | W7: 1 | X7: 1 | Y7: 1
A8: Valor de los equipos al año 10 (1 = se cuenta) | B8: 1 | C8: 0 | D8: 0 | E8: 1 | F8: 1 | G8: 1 | H8: 1 | I8: 1 | J8: 1 | K8: 1 | L8: 1 | M8: 1 | N8: 1 | O8: 1 | P8: 1 | Q8: 1 | R8: 1 | S8: 1 | T8: 1 | U8: 1 | V8: 1 | W8: 1 | X8: 1 | Y8: 1
A9: Relevo natural de 2 operarios (1 = se cuenta) | B9: 1 | C9: 1 | D9: 1 | E9: 1 | F9: 0 | G9: 1 | H9: 1 | I9: 1 | J9: 1 | K9: 1 | L9: 1 | M9: 1 | N9: 1 | O9: 1 | P9: 1 | Q9: 1 | R9: 1 | S9: 1 | T9: 1 | U9: 1 | V9: 1 | W9: 1 | X9: 1 | Y9: 1
A10: Factor de beneficios | B10: 1 | C10: 1 | D10: 1 | E10: 1 | F10: 1 | G10: 0.8 | H10: 1.2 | I10: 1 | J10: 1 | K10: 1 | L10: 1 | M10: 1 | N10: 1 | O10: 1 | P10: 1 | Q10: 1 | R10: 1 | S10: 1 | T10: 1 | U10: 1 | V10: 0.8 | W10: 1 | X10: 1 | Y10: 1
A11: Factor de inversión | B11: 1 | C11: 1 | D11: 1 | E11: 1 | F11: 1 | G11: 1 | H11: 1 | I11: 1.2 | J11: 0.8 | K11: 1 | L11: 1 | M11: 1 | N11: 1 | O11: 1 | P11: 1 | Q11: 1 | R11: 1 | S11: 1 | T11: 1 | U11: 1 | V11: 1.2 | W11: 1 | X11: 1 | Y11: 1
A12: Factor de costos operativos nuevos | B12: 1 | C12: 1 | D12: 1 | E12: 1 | F12: 1 | G12: 1 | H12: 1 | I12: 1 | J12: 1 | K12: 1.3 | L12: 0.7 | M12: 1 | N12: 1 | O12: 1 | P12: 1 | Q12: 1 | R12: 1 | S12: 1 | T12: 1 | U12: 1 | V12: 1.3 | W12: 1 | X12: 1 | Y12: 1
A13: Garantía del crédito (0 = prenda sobre los equipos; 1 = FNG) | B13: =Quesería!$B$48 -> 0 | C13: 1 | D13: 1 | E13: =Quesería!$B$48 -> 0 | F13: =Quesería!$B$48 -> 0 | G13: =Quesería!$B$48 -> 0 | H13: =Quesería!$B$48 -> 0 | I13: =Quesería!$B$48 -> 0 | J13: =Quesería!$B$48 -> 0 | K13: =Quesería!$B$48 -> 0 | L13: =Quesería!$B$48 -> 0 | ... R13: =Quesería!$B$48 -> 0 | S13: 1 | T13: =Quesería!$B$48 -> 0 | U13: 1 | V13: =Quesería!$B$48 -> 0 | W13: 1 | X13: 1 | Y13: =Quesería!$B$48 -> 0
A14: Tasa del crédito | B14: =Quesería!$B$41 -> 0.141 | C14: =Quesería!$B$41 -> 0.141 | D14: =Quesería!$B$41 -> 0.141 | E14: =Quesería!$B$41 -> 0.141 | F14: =Quesería!$B$41 -> 0.141 | G14: =Quesería!$B$41 -> 0.141 | H14: =Quesería!$B$41 -> 0.141 | I14: =Quesería!$B$41 -> 0.141 | ... Q14: =Quesería!$B$41 -> 0.141 | R14: 0.157 | S14: =Quesería!$B$41 -> 0.141 | T14: =Quesería!$B$41 -> 0.141 | U14: =Quesería!$B$41 -> 0.141 | V14: =Quesería!$B$41 -> 0.141 | W14: =Quesería!$B$41 -> 0.141 | X14: =Quesería!$B$41 -> 0.141 | Y14: =Quesería!$B$41 -> 0.141
A15: Ruta de inflación (1 base, 2 consenso, 3 persistente) | B15: =Quesería!$B$6 -> 1 | C15: =Quesería!$B$6 -> 1 | D15: =Quesería!$B$6 -> 1 | E15: =Quesería!$B$6 -> 1 | F15: =Quesería!$B$6 -> 1 | G15: =Quesería!$B$6 -> 1 | H15: =Quesería!$B$6 -> 1 | I15: =Quesería!$B$6 -> 1 | ... L15: =Quesería!$B$6 -> 1 | M15: 2 | N15: 3 | O15: =Quesería!$B$6 -> 1 | P15: =Quesería!$B$6 -> 1 | Q15: =Quesería!$B$6 -> 1 | R15: =Quesería!$B$6 -> 1 | S15: =Quesería!$B$6 -> 1 | T15: =Quesería!$B$6 -> 1 | U15: =Quesería!$B$6 -> 1 | V15: =Quesería!$B$6 -> 1 | ... Y15: =Quesería!$B$6 -> 1
A16: Incremento del salario mínimo de 2027 | B16: =Entorno!$B$12 -> 0.085 | C16: =Entorno!$B$12 -> 0.085 | D16: =Entorno!$B$12 -> 0.085 | E16: =Entorno!$B$12 -> 0.085 | F16: =Entorno!$B$12 -> 0.085 | G16: =Entorno!$B$12 -> 0.085 | H16: =Entorno!$B$12 -> 0.085 | I16: =Entorno!$B$12 -> 0.085 | ... N16: =Entorno!$B$12 -> 0.085 | O16: 0.07 | P16: 0.1 | Q16: =Entorno!$B$12 -> 0.085 | R16: =Entorno!$B$12 -> 0.085 | S16: =Entorno!$B$12 -> 0.085 | T16: =Entorno!$B$12 -> 0.085 | U16: =Entorno!$B$12 -> 0.085 | V16: =Entorno!$B$12 -> 0.085 | W16: =Entorno!$B$12 -> 0.085 | X16: =Entorno!$B$12 -> 0.085 | Y16: =Entorno!$B$12 -> 0.085
A17: Impuesto de renta | B17: =Quesería!$B$10 -> 0.35 | C17: =Quesería!$B$10 -> 0.35 | D17: =Quesería!$B$10 -> 0.35 | E17: =Quesería!$B$10 -> 0.35 | F17: =Quesería!$B$10 -> 0.35 | G17: =Quesería!$B$10 -> 0.35 | H17: =Quesería!$B$10 -> 0.35 | I17: =Quesería!$B$10 -> 0.35 | ... P17: =Quesería!$B$10 -> 0.35 | Q17: 0.3 | R17: =Quesería!$B$10 -> 0.35 | S17: =Quesería!$B$10 -> 0.35 | T17: =Quesería!$B$10 -> 0.35 | U17: =Quesería!$B$10 -> 0.35 | V17: =Quesería!$B$10 -> 0.35 | W17: =Quesería!$B$10 -> 0.35 | X17: =Quesería!$B$10 -> 0.35 | Y17: =Quesería!$B$10 -> 0.35
A18: Costo de capital (1 = del proyecto; 0 = 16 % de la empresa) | B18: 1 | C18: 1 | D18: 1 | E18: 1 | F18: 1 | G18: 1 | H18: 1 | I18: 1 | J18: 1 | K18: 1 | L18: 1 | M18: 1 | N18: 1 | O18: 1 | P18: 1 | Q18: 1 | R18: 1 | S18: 1 | T18: 1 | U18: 1 | V18: 1 | W18: 0 | X18: 1 | Y18: 1
A19: Depreciación fiscal por tipo de activo (1 = sí; 0 = todo a 10 años) | B19: 1 | C19: 1 | D19: 1 | E19: 1 | F19: 1 | G19: 1 | H19: 1 | I19: 1 | J19: 1 | K19: 1 | L19: 1 | M19: 1 | N19: 1 | O19: 1 | P19: 1 | Q19: 1 | R19: 1 | S19: 1 | T19: 1 | U19: 1 | V19: 1 | W19: 0 | X19: 0 | Y19: 1
A20: Crédito fiscal por innovación, art. 256-1 (1 = certificado) | B20: =Quesería!$B$49 -> 1 | C20: 0 | D20: 0 | E20: =Quesería!$B$49 -> 1 | F20: =Quesería!$B$49 -> 1 | G20: =Quesería!$B$49 -> 1 | H20: =Quesería!$B$49 -> 1 | I20: =Quesería!$B$49 -> 1 | J20: =Quesería!$B$49 -> 1 | K20: =Quesería!$B$49 -> 1 | L20: =Quesería!$B$49 -> 1 | ... S20: =Quesería!$B$49 -> 1 | T20: 0 | U20: 0 | V20: =Quesería!$B$49 -> 1 | W20: 0 | X20: 0 | Y20: =Quesería!$B$49 -> 1
A21: Etapa 2 (1 = se hace) | B21: 1 | C21: 1 | D21: 0 | E21: 1 | F21: 1 | G21: 1 | H21: 1 | I21: 1 | J21: 1 | K21: 1 | L21: 1 | M21: 1 | N21: 1 | O21: 1 | P21: 1 | Q21: 1 | R21: 1 | S21: 1 | T21: 1 | U21: 1 | V21: 1 | W21: 1 | X21: 1 | Y21: 0
A22: Beneficios según su respaldo (1 = caso conservador) | B22: 0 | C22: 1 | D22: 1 | E22: 0 | F22: 0 | G22: 0 | H22: 0 | I22: 0 | J22: 0 | K22: 0 | L22: 0 | M22: 0 | N22: 0 | O22: 0 | P22: 0 | Q22: 0 | R22: 0 | S22: 0 | T22: 0 | U22: 0 | V22: 0 | W22: 0 | X22: 0 | Y22: 0
A23: Arranque de la etapa 1 en 2027 (1 = se cuenta) | B23: 1 | C23: 1 | D23: 1 | E23: 0 | F23: 1 | G23: 1 | H23: 1 | I23: 1 | J23: 1 | K23: 1 | L23: 1 | M23: 1 | N23: 1 | O23: 1 | P23: 1 | Q23: 1 | R23: 1 | S23: 1 | T23: 1 | U23: 1 | V23: 1 | W23: 1 | X23: 1 | Y23: 1
A24: Ajuste de las tasas nominales por la inflación de la ruta (Fisher) | B24: =CHOOSE(B$15,Entorno!$M$7,Entorno!$M$8,Entorno!$M$9)-CHOOSE(Quesería!$B$6,Entorno!$M$7,Entorno!$M$8,Entorno!$M$9) -> 0 | C24: =CHOOSE(C$15,Entorno!$M$7,Entorno!$M$8,Entorno!$M$9)-CHOOSE(Quesería!$B$6,Entorno!$M$7,Entorno!$M$8,Entorno!$M$9) -> 0 | D24: =CHOOSE(D$15,Entorno!$M$7,Entorno!$M$8,Entorno!$M$9)-CHOOSE(Quesería!$B$6,Entorno!$M$7,Entorno!$M$8,Entorno!$M$9) -> 0 | E24: =CHOOSE(E$15,Entorno!$M$7,Entorno!$M$8,Entorno!$M$9)-CHOOSE(Quesería!$B$6,Entorno!$M$7,Entorno!$M$8,Entorno!$M$9) -> 0 | F24: =CHOOSE(F$15,Entorno!$M$7,Entorno!$M$8,Entorno!$M$9)-CHOOSE(Quesería!$B$6,Entorno!$M$7,Entorno!$M$8,Entorno!$M$9) -> 0 | G24: =CHOOSE(G$15,Entorno!$M$7,Entorno!$M$8,Entorno!$M$9)-CHOOSE(Quesería!$B$6,Entorno!$M$7,Entorno!$M$8,Entorno!$M$9) -> 0 | H24: =CHOOSE(H$15,Entorno!$M$7,Entorno!$M$8,Entorno!$M$9)-CHOOSE(Quesería!$B$6,Entorno!$M$7,Entorno!$M$8,Entorno!$M$9) -> 0 | I24: =CHOOSE(I$15,Entorno!$M$7,Entorno!$M$8,Entorno!$M$9)-CHOOSE(Quesería!$B$6,Entorno!$M$7,Entorno!$M$8,Entorno!$M$9) -> 0 | ... Y24: =CHOOSE(Y$15,Entorno!$M$7,Entorno!$M$8,Entorno!$M$9)-CHOOSE(Quesería!$B$6,Entorno!$M$7,Entorno!$M$8,Entorno!$M$9) -> 0
A25: Costo de capital del proyecto | B25: =IF(B$18=1,Quesería!$B$40*(B$14+B$24+B$13*Quesería!$B$44*1.19)*(1-B$17)+(1-Quesería!$B$40)*(Quesería!$B$46+B$24),Quesería!$B$7+B$24) -> 0.139155 | C25: =IF(C$18=1,Quesería!$B$40*(C$14+C$24+C$13*Quesería!$B$44*1.19)*(1-C$17)+(1-Quesería!$B$40)*(Quesería!$B$46+C$24),Quesería!$B$7+C$24) -> 0.14992986 | D25: =IF(D$18=1,Quesería!$B$40*(D$14+D$24+D$13*Quesería!$B$44*1.19)*(1-D$17)+(1-Quesería!$B$40)*(Quesería!$B$46+D$24),Quesería!$B$7+D$24) -> 0.14992986 | E25: =IF(E$18=1,Quesería!$B$40*(E$14+E$24+E$13*Quesería!$B$44*1.19)*(1-E$17)+(1-Quesería!$B$40)*(Quesería!$B$46+E$24),Quesería!$B$7+E$24) -> 0.139155 | F25: =IF(F$18=1,Quesería!$B$40*(F$14+F$24+F$13*Quesería!$B$44*1.19)*(1-F$17)+(1-Quesería!$B$40)*(Quesería!$B$46+F$24),Quesería!$B$7+F$24) -> 0.139155 | G25: =IF(G$18=1,Quesería!$B$40*(G$14+G$24+G$13*Quesería!$B$44*1.19)*(1-G$17)+(1-Quesería!$B$40)*(Quesería!$B$46+G$24),Quesería!$B$7+G$24) -> 0.139155 | H25: =IF(H$18=1,Quesería!$B$40*(H$14+H$24+H$13*Quesería!$B$44*1.19)*(1-H$17)+(1-Quesería!$B$40)*(Quesería!$B$46+H$24),Quesería!$B$7+H$24) -> 0.139155 | I25: =IF(I$18=1,Quesería!$B$40*(I$14+I$24+I$13*Quesería!$B$44*1.19)*(1-I$17)+(1-Quesería!$B$40)*(Quesería!$B$46+I$24),Quesería!$B$7+I$24) -> 0.139155 | ... Y25: =IF(Y$18=1,Quesería!$B$40*(Y$14+Y$24+Y$13*Quesería!$B$44*1.19)*(1-Y$17)+(1-Quesería!$B$40)*(Quesería!$B$46+Y$24),Quesería!$B$7+Y$24) -> 0.139155
A26: Conservador: cada beneficio según su respaldo (contratado y medido 100 %, técnicamente justificado 75 %, por medir 50 %, hipotético 0 %), sin descuento ambiental ni crédito fiscal, con garantía del FNG y sin valor final de los equipos. Conservador con compuerta: lo mismo, pero la etapa 2 no se hace porque sus condiciones no se cumplen. Las rutas de inflación mueven las tasas nominales en la misma proporción (Fisher). Crédito ordinario: 15,7 %, tasa de los créditos empresariales a medianas empresas a 3–5 años en la misma fuente. Garantía del FNG: si el banco no acepta la prenda. Sin crédito fiscal: si el CNBT no certifica la inversión. Renta 30 %: si prospera la reducción anunciada por el Gobierno. Adverso combinado: beneficios −20 %, inversión +20 % y costos +30 % a la vez. Los escenarios de herramientas se explican en la hoja Herramientas.
A28: Resultados por escenario
B29: Oferta | C29: Conservador | D29: Conservador con compuerta | E29: Sin arranque en 2027 | F29: Sin relevo natural | G29: Beneficios −20 % | H29: Beneficios +20 % | I29: Inversión +20 % | J29: Inversión −20 % | K29: Costos operativos +30 % | L29: Costos operativos −30 % | M29: Inflación del consenso | N29: Inflación persistente | O29: Salario mínimo 2027: 7 % | P29: Salario mínimo 2027: 10 % | Q29: Renta 30 % | R29: Crédito ordinario | S29: Garantía del FNG | T29: Sin crédito fiscal por innovación | U29: Sin las dos gestiones | V29: Adverso combinado | W29: Sin herramientas | X29: Con el costo de capital del proyecto | Y29: Solo etapas 0 y 1
A30: Costo de capital del proyecto | B30: =$B$25 -> 0.139155 | C30: =$C$25 -> 0.14992986 | D30: =$D$25 -> 0.14992986 | E30: =$E$25 -> 0.139155 | F30: =$F$25 -> 0.139155 | G30: =$G$25 -> 0.139155 | H30: =$H$25 -> 0.139155 | I30: =$I$25 -> 0.139155 | J30: =$J$25 -> 0.139155 | K30: =$K$25 -> 0.139155 | L30: =$L$25 -> 0.139155 | M30: =$M$25 -> 0.13489286 | N30: =$N$25 -> 0.15564123 | O30: =$O$25 -> 0.139155 | P30: =$P$25 -> 0.139155 | Q30: =$Q$25 -> 0.14409 | R30: =$R$25 -> 0.146435 | S30: =$S$25 -> 0.14992986 | T30: =$T$25 -> 0.139155 | U30: =$U$25 -> 0.14992986 | V30: =$V$25 -> 0.139155 | W30: =$W$25 -> 0.16 | X30: =$X$25 -> 0.14992986 | Y30: =$Y$25 -> 0.139155
A31: TIR del proyecto en pesos corrientes (frente al costo de capital) | B31: =IRR(B68:L68) -> 0.21421387 | C31: =IRR(B111:L111) -> 0.062952682 | D31: =IRR(B154:L154) -> 0.057937208 | E31: =IRR(B197:L197) -> 0.2066915 | F31: =IRR(B240:L240) -> 0.16039918 | G31: =IRR(B283:L283) -> 0.15125665 | H31: =IRR(B326:L326) -> 0.27173209 | I31: =IRR(B369:L369) -> 0.17059022 | J31: =IRR(B412:L412) -> 0.27467606 | K31: =IRR(B455:L455) -> 0.1946857 | L31: =IRR(B498:L498) -> 0.23317777 | M31: =IRR(B541:L541) -> 0.20842777 | N31: =IRR(B584:L584) -> 0.23525123 | O31: =IRR(B627:L627) -> 0.21330547 | P31: =IRR(B670:L670) -> 0.21512052 | Q31: =IRR(B713:L713) -> 0.2250889 | R31: =IRR(B756:L756) -> 0.21421387 | S31: =IRR(B799:L799) -> 0.21421387 | T31: =IRR(B842:L842) -> 0.17926805 | U31: =IRR(B885:L885) -> 0.17926805 | V31: =IRR(B928:L928) -> 0.09300273 | W31: =IRR(B971:L971) -> 0.17427009 | X31: =IRR(B1014:L1014) -> 0.17427009 | Y31: =IRR(B1057:L1057) -> 0.24010284
A32: TIR del proyecto en pesos constantes | B32: =IRR(B67:L67) -> 0.16467046 | C32: =IRR(B110:L110) -> 0.020128529 | D32: =IRR(B153:L153) -> 0.014477445 | E32: =IRR(B196:L196) -> 0.15746907 | F32: =IRR(B239:L239) -> 0.11322879 | G32: =IRR(B282:L282) -> 0.10448845 | H32: =IRR(B325:L325) -> 0.21963093 | I32: =IRR(B368:L368) -> 0.12296903 | J32: =IRR(B411:L411) -> 0.22244945 | K32: =IRR(B454:L454) -> 0.14600996 | L32: =IRR(B497:L497) -> 0.18278915 | M32: =IRR(B540:L540) -> 0.16616325 | N32: =IRR(B583:L583) -> 0.15986031 | O32: =IRR(B626:L626) -> 0.1638021 | P32: =IRR(B669:L669) -> 0.16553712 | Q32: =IRR(B712:L712) -> 0.17506959 | R32: =IRR(B755:L755) -> 0.16467046 | S32: =IRR(B798:L798) -> 0.16467046 | T32: =IRR(B841:L841) -> 0.13142032 | U32: =IRR(B884:L884) -> 0.13142032 | V32: =IRR(B927:L927) -> 0.048778661 | W32: =IRR(B970:L970) -> 0.12662818 | X32: =IRR(B1013:L1013) -> 0.12662818 | Y32: =IRR(B1056:L1056) -> 0.18783588
A33: VPN al costo de capital ($ M de 2026) | B33: =SUMPRODUCT(B67:L67,B71:L71) -> 367.41984 | C33: =SUMPRODUCT(B110:L110,B114:L114) -> -396.60213 | D33: =SUMPRODUCT(B153:L153,B157:L157) -> -209.22818 | E33: =SUMPRODUCT(B196:L196,B200:L200) -> 338.06199 | F33: =SUMPRODUCT(B239:L239,B243:L243) -> 97.936235 | G33: =SUMPRODUCT(B282:L282,B286:L286) -> 55.947949 | H33: =SUMPRODUCT(B325:L325,B329:L329) -> 678.89173 | I33: =SUMPRODUCT(B368:L368,B372:L372) -> 177.39427 | J33: =SUMPRODUCT(B411:L411,B415:L415) -> 557.44542 | K33: =SUMPRODUCT(B454:L454,B458:L458) -> 267.23581 | L33: =SUMPRODUCT(B497:L497,B501:L501) -> 467.60387 | M33: =SUMPRODUCT(B540:L540,B544:L544) -> 359.36482 | N33: =SUMPRODUCT(B583:L583,B587:L587) -> 391.67116 | O33: =SUMPRODUCT(B626:L626,B630:L630) -> 362.58857 | P33: =SUMPRODUCT(B669:L669,B673:L673) -> 372.25111 | Q33: =SUMPRODUCT(B712:L712,B716:L716) -> 396.09283 | R33: =SUMPRODUCT(B755:L755,B759:L759) -> 323.12592 | S33: =SUMPRODUCT(B798:L798,B802:L802) -> 302.64226 | T33: =SUMPRODUCT(B841:L841,B845:L845) -> 213.60067 | U33: =SUMPRODUCT(B884:L884,B888:L888) -> 150.26438 | V33: =SUMPRODUCT(B927:L927,B931:L931) -> -240.57876 | W33: =SUMPRODUCT(B970:L970,B974:L974) -> 72.665882 | X33: =SUMPRODUCT(B1013:L1013,B1017:L1017) -> 128.42404 | Y33: =SUMPRODUCT(B1056:L1056,B1060:L1060) -> 230.72914
A34: Recuperación (años) | B34: =SUM(B70:L70) -> 5.1086246 | C34: =SUM(B113:L113) -> 9.1444375 | D34: =SUM(B156:L156) -> 9.3454343 | E34: =SUM(B199:L199) -> 5.2500686 | F34: =SUM(B242:L242) -> 6.2962931 | G34: =SUM(B285:L285) -> 6.4997148 | H34: =SUM(B328:L328) -> 4.2317242 | I34: =SUM(B371:L371) -> 6.0695033 | J34: =SUM(B414:L414) -> 4.1981579 | K34: =SUM(B457:L457) -> 5.5101944 | L34: =SUM(B500:L500) -> 4.7773802 | M34: =SUM(B543:L543) -> 5.0812319 | N34: =SUM(B586:L586) -> 5.1956736 | O34: =SUM(B629:L629) -> 5.125911 | P34: =SUM(B672:L672) -> 5.0914875 | Q34: =SUM(B715:L715) -> 4.9228841 | R34: =SUM(B758:L758) -> 5.1086246 | S34: =SUM(B801:L801) -> 5.1086246 | T34: =SUM(B844:L844) -> 5.9075513 | U34: =SUM(B887:L887) -> 5.9075513 | V34: =SUM(B930:L930) -> 8.2278054 | W34: =SUM(B973:L973) -> 6.027743 | X34: =SUM(B1016:L1016) -> 6.027743 | Y34: =SUM(B1059:L1059) -> 3.8396594
A35: Recuperación descontada (años) | B35: =IF(SUM(B74:L74)=0,"Más de 10",SUM(B74:L74)) -> 6.9418802 | C35: =IF(SUM(B117:L117)=0,"Más de 10",SUM(B117:L117)) -> Más de 10 | D35: =IF(SUM(B160:L160)=0,"Más de 10",SUM(B160:L160)) -> Más de 10 | E35: =IF(SUM(B203:L203)=0,"Más de 10",SUM(B203:L203)) -> 7.1775309 | F35: =IF(SUM(B246:L246)=0,"Más de 10",SUM(B246:L246)) -> 9.0960877 | G35: =IF(SUM(B289:L289)=0,"Más de 10",SUM(B289:L289)) -> 9.4670148 | H35: =IF(SUM(B332:L332)=0,"Más de 10",SUM(B332:L332)) -> 5.4887347 | I35: =IF(SUM(B375:L375)=0,"Más de 10",SUM(B375:L375)) -> 8.611522 | J35: =IF(SUM(B418:L418)=0,"Más de 10",SUM(B418:L418)) -> 5.4264531 | K35: =IF(SUM(B461:L461)=0,"Más de 10",SUM(B461:L461)) -> 7.6082508 | L35: =IF(SUM(B504:L504)=0,"Más de 10",SUM(B504:L504)) -> 6.4220156 | M35: =IF(SUM(B547:L547)=0,"Más de 10",SUM(B547:L547)) -> 6.965895 | N35: =IF(SUM(B590:L590)=0,"Más de 10",SUM(B590:L590)) -> 6.8998148 | O35: =IF(SUM(B633:L633)=0,"Más de 10",SUM(B633:L633)) -> 6.9681585 | P35: =IF(SUM(B676:L676)=0,"Más de 10",SUM(B676:L676)) -> 6.9157894 | Q35: =IF(SUM(B719:L719)=0,"Más de 10",SUM(B719:L719)) -> 6.7615991 | R35: =IF(SUM(B762:L762)=0,"Más de 10",SUM(B762:L762)) -> 7.1420269 | S35: =IF(SUM(B805:L805)=0,"Más de 10",SUM(B805:L805)) -> 7.2463687 | T35: =IF(SUM(B848:L848)=0,"Más de 10",SUM(B848:L848)) -> 8.2288547 | U35: =IF(SUM(B891:L891)=0,"Más de 10",SUM(B891:L891)) -> 8.6735057 | V35: =IF(SUM(B934:L934)=0,"Más de 10",SUM(B934:L934)) -> Más de 10 | W35: =IF(SUM(B977:L977)=0,"Más de 10",SUM(B977:L977)) -> 9.332824 | X35: =IF(SUM(B1020:L1020)=0,"Más de 10",SUM(B1020:L1020)) -> 8.9066379 | Y35: =IF(SUM(B1063:L1063)=0,"Más de 10",SUM(B1063:L1063)) -> 5.8022963
A36: ROI a 10 años | B36: =SUM(B67:L67)/SUM(B50:L50) -> 0.98500824 | C36: =SUM(B110:L110)/SUM(B93:L93) -> 0.11292459 | D36: =SUM(B153:L153)/SUM(B136:L136) -> 0.080052427 | E36: =SUM(B196:L196)/SUM(B179:L179) -> 0.96169896 | F36: =SUM(B239:L239)/SUM(B222:L222) -> 0.63259645 | G36: =SUM(B282:L282)/SUM(B265:L265) -> 0.584285 | H36: =SUM(B325:L325)/SUM(B308:L308) -> 1.3857315 | I36: =SUM(B368:L368)/SUM(B351:L351) -> 0.7016812 | J36: =SUM(B411:L411)/SUM(B394:L394) -> 1.4099988 | K36: =SUM(B454:L454)/SUM(B437:L437) -> 0.85613046 | L36: =SUM(B497:L497)/SUM(B480:L480) -> 1.113886 | M36: =SUM(B540:L540)/SUM(B523:L523) -> 0.9953056 | N36: =SUM(B583:L583)/SUM(B566:L566) -> 0.95072964 | O36: =SUM(B626:L626)/SUM(B609:L609) -> 0.97864244 | P36: =SUM(B669:L669)/SUM(B652:L652) -> 0.99137404 | Q36: =SUM(B712:L712)/SUM(B695:L695) -> 1.0675878 | R36: =SUM(B755:L755)/SUM(B738:L738) -> 0.98500824 | S36: =SUM(B798:L798)/SUM(B781:L781) -> 0.98500824 | T36: =SUM(B841:L841)/SUM(B824:L824) -> 0.85334901 | U36: =SUM(B884:L884)/SUM(B867:L867) -> 0.85334901 | V36: =SUM(B927:L927)/SUM(B910:L910) -> 0.25357289 | W36: =SUM(B970:L970)/SUM(B953:L953) -> 0.84619713 | X36: =SUM(B1013:L1013)/SUM(B996:L996) -> 0.84619713 | Y36: =SUM(B1056:L1056)/SUM(B1039:L1039) -> 1.0367483
A37: TIR del inversionista en pesos corrientes (frente al 25 %) | B37: =IRR(B83:L83) -> 0.41220926 | C37: =IRR(B126:L126) -> 0.016139976 | D37: =IRR(B169:L169) -> 0.0064963028 | E37: =IRR(B212:L212) -> 0.37516016 | F37: =IRR(B255:L255) -> 0.26745542 | G37: =IRR(B298:L298) -> 0.23939592 | H37: =IRR(B341:L341) -> 0.57813119 | I37: =IRR(B384:L384) -> 0.29210452 | J37: =IRR(B427:L427) -> 0.58413731 | K37: =IRR(B470:L470) -> 0.35767526 | L37: =IRR(B513:L513) -> 0.46572676 | M37: =IRR(B556:L556) -> 0.4072185 | N37: =IRR(B599:L599) -> 0.42760989 | O37: =IRR(B642:L642) -> 0.40982105 | P37: =IRR(B685:L685) -> 0.41459142 | Q37: =IRR(B728:L728) -> 0.42432534 | R37: =IRR(B771:L771) -> 0.39182372 | S37: =IRR(B814:L814) -> 0.37457397 | T37: =IRR(B857:L857) -> 0.28038084 | U37: =IRR(B900:L900) -> 0.25681294 | V37: =IRR(B943:L943) -> 0.092323305 | W37: =IRR(B986:L986) -> 0.24052487 | X37: =IRR(B1029:L1029) -> 0.24052487 | Y37: =IRR(B1072:L1072) -> 0.58607666
A38: TIR del inversionista en pesos constantes | B38: =IRR(B82:L82) -> 0.35343032 | C38: =IRR(B125:L125) -> -0.024019507 | D38: =IRR(B168:L168) -> -0.033548452 | E38: =IRR(B211:L211) -> 0.31813769 | F38: =IRR(B254:L254) -> 0.21561312 | G38: =IRR(B297:L297) -> 0.18889791 | H38: =IRR(B340:L340) -> 0.51139463 | I38: =IRR(B383:L383) -> 0.23907902 | J38: =IRR(B426:L426) -> 0.51714341 | K38: =IRR(B469:L469) -> 0.30153207 | L38: =IRR(B512:L512) -> 0.40436105 | M38: =IRR(B555:L555) -> 0.35669793 | N38: =IRR(B598:L598) -> 0.34047877 | O38: =IRR(B641:L641) -> 0.3511556 | P38: =IRR(B684:L684) -> 0.3556993 | Q38: =IRR(B727:L727) -> 0.36503364 | R38: =IRR(B770:L770) -> 0.33409475 | S38: =IRR(B813:L813) -> 0.3177285 | T38: =IRR(B856:L856) -> 0.22837889 | U38: =IRR(B899:L899) -> 0.20595132 | V38: =IRR(B942:L942) -> 0.048708834 | W38: =IRR(B985:L985) -> 0.19033771 | X38: =IRR(B1028:L1028) -> 0.19033771 | Y38: =IRR(B1071:L1071) -> 0.51496835
A39: Cobertura mínima del servicio de la deuda | B39: =MIN(D86:L86) -> 1.2094267 | C39: =MIN(D129:L129) -> 0.79546539 | D39: =MIN(D172:L172) -> 0.5906165 | E39: =MIN(D215:L215) -> 1.2094267 | F39: =MIN(D258:L258) -> 1.0036778 | G39: =MIN(D301:L301) -> 0.98254661 | H39: =MIN(D344:L344) -> 1.4363068 | I39: =MIN(D387:L387) -> 1.0482634 | J39: =MIN(D430:L430) -> 1.4511717 | K39: =MIN(D473:L473) -> 1.1360422 | L39: =MIN(D516:L516) -> 1.2828112 | M39: =MIN(D559:L559) -> 1.211207 | N39: =MIN(D602:L602) -> 1.1945178 | O39: =MIN(D645:L645) -> 1.2056531 | P39: =MIN(D688:L688) -> 1.2132003 | Q39: =MIN(D731:L731) -> 1.2332549 | R39: =MIN(D774:L774) -> 1.1687911 | S39: =MIN(D817:L817) -> 1.1606656 | T39: =MIN(D860:L860) -> 1.2094267 | U39: =MIN(D903:L903) -> 1.1606656 | V39: =MIN(D946:L946) -> 0.78943947 | W39: =MIN(D989:L989) -> 1.1634435 | X39: =MIN(D1032:L1032) -> 1.1634435 | Y39: =MIN(D1075:L1075) -> 1.0715971
A41: Flujos de cada escenario (años 0 a 10)
A42: $ M | B42: Año 0 | C42: Año 1 | D42: Año 2 | E42: Año 3 | F42: Año 4 | G42: Año 5 | H42: Año 6 | I42: Año 7 | J42: Año 8 | K42: Año 9 | L42: Año 10
A43: Año (número) | B43: 0 | C43: 1 | D43: 2 | E43: 3 | F43: 4 | G43: 5 | H43: 6 | I43: 7 | J43: 8 | K43: 9 | L43: 10
...

Sheet Riesgo
A1: Análisis de riesgo de la oferta
A2: Cuánto puede empeorar cada supuesto antes de que el proyecto deje de valer la pena, y qué supuestos pesan más. Se calcula con la hoja Escenarios.
A4: Punto de equilibrio: variación que deja el VPN en cero
A5: Supuesto | B5: Variación de equilibrio | C5: Valor de equilibrio | D5: Valor de la oferta | F5: Lectura
A6: Beneficios | B6: =-0.2*Escenarios!$B$33/(Escenarios!$B$33-Escenarios!$G$33) -> -0.23592488 | C6: =D6*(1+B6) -> 316.11582 | D6: =Quesería!$E$111 -> 413.72349 | F6: Los beneficios pueden caer esta fracción y el proyecto todavía devuelve su costo de capital.
A7: Inversión | B7: =0.2*Escenarios!$B$33/(Escenarios!$B$33-Escenarios!$I$33) -> 0.38670568 | C7: =D7*(1+B7) -> 1757.6685 | D7: =Quesería!$F$85 -> 1267.5137 | F7: La inversión puede subir esta fracción, además de los imprevistos que ya incluye.
A8: Costos operativos nuevos | B8: =0.3*Escenarios!$B$33/(Escenarios!$B$33-Escenarios!$K$33) -> 1.1002348 | C8: =D8*(1+B8) -> 186.51451 | D8: =Quesería!$E$112 -> 88.806504 | F8: Los costos nuevos pueden subir esta fracción.
A9: El VPN cambia en línea recta con cada factor; por eso basta un escenario para hallar el punto donde se hace cero. En ese punto la TIR en pesos corrientes iguala el costo de capital.
A11: Sensibilidad del VPN (gráfico de tornado)
A12: Supuesto | B12: VPN con el valor desfavorable | C12: VPN con el valor favorable | D12: Cambio desfavorable | E12: Cambio favorable | F12: Valores probados
A13: Beneficios | B13: =MIN(Escenarios!$G$33,Escenarios!$H$33) -> 55.947949 | C13: =MAX(Escenarios!$G$33,Escenarios!$H$33) -> 678.89173 | D13: =B13-Escenarios!$B$33 -> -311.47189 | E13: =C13-Escenarios!$B$33 -> 311.47189 | F13: −20 % / +20 %
A14: Relevo natural | B14: =MIN(Escenarios!$F$33,Escenarios!$B$33) -> 97.936235 | C14: =MAX(Escenarios!$F$33,Escenarios!$B$33) -> 367.41984 | D14: =B14-Escenarios!$B$33 -> -269.48361 | E14: =C14-Escenarios!$B$33 -> 0 | F14: Sin relevo / con relevo
A15: Inversión | B15: =MIN(Escenarios!$I$33,Escenarios!$J$33) -> 177.39427 | C15: =MAX(Escenarios!$I$33,Escenarios!$J$33) -> 557.44542 | D15: =B15-Escenarios!$B$33 -> -190.02557 | E15: =C15-Escenarios!$B$33 -> 190.02557 | F15: +20 % / −20 %
A16: Costos operativos nuevos | B16: =MIN(Escenarios!$K$33,Escenarios!$L$33) -> 267.23581 | C16: =MAX(Escenarios!$K$33,Escenarios!$L$33) -> 467.60387 | D16: =B16-Escenarios!$B$33 -> -100.18403 | E16: =C16-Escenarios!$B$33 -> 100.18403 | F16: +30 % / −30 %
A17: Supuestos del escenario conservador | B17: =MIN(Escenarios!$C$33,Escenarios!$B$33) -> -396.60213 | C17: =MAX(Escenarios!$C$33,Escenarios!$B$33) -> 367.41984 | D17: =B17-Escenarios!$B$33 -> -764.02197 | E17: =C17-Escenarios!$B$33 -> 0 | F17: Beneficios según su respaldo / oferta
A18: Inflación | B18: =MIN(Escenarios!$M$33,Escenarios!$N$33) -> 359.36482 | C18: =MAX(Escenarios!$M$33,Escenarios!$N$33) -> 391.67116 | D18: =B18-Escenarios!$B$33 -> -8.0550222 | E18: =C18-Escenarios!$B$33 -> 24.251319 | F18: Consenso de analistas / persistente
A19: Salario mínimo de 2027 | B19: =MIN(Escenarios!$O$33,Escenarios!$P$33) -> 362.58857 | C19: =MAX(Escenarios!$O$33,Escenarios!$P$33) -> 372.25111 | D19: =B19-Escenarios!$B$33 -> -4.8312716 | E19: =C19-Escenarios!$B$33 -> 4.8312716 | F19: 7 % / 10 %
A20: Gestiones de IntegraMotion (prenda y crédito fiscal) | B20: =MIN(Escenarios!$U$33,Escenarios!$B$33) -> 150.26438 | C20: =MAX(Escenarios!$U$33,Escenarios!$B$33) -> 367.41984 | D20: =B20-Escenarios!$B$33 -> -217.15547 | E20: =C20-Escenarios!$B$33 -> 0 | F20: Sin ellas / con ellas
A21: VPN de la oferta ($ M) | B21: =Escenarios!$B$33 -> 367.41984
A22: Inflación: las tasas nominales se mueven con la inflación de cada ruta, así que el cambio de VPN viene solo de lo pactado en pesos corrientes (deuda, depreciación fiscal, IVA y cartera). Salario mínimo: si sube más, valen más las horas extra y el relevo que se ahorran.
A41: Resultados por escenario
A42: Escenario | B42: TIR en pesos corrientes | C42: VPN ($ M) | D42: TIR del inversionista | E42: Cobertura mínima | F42: Lectura
A43: Oferta | B43: =Escenarios!$B$31 -> 0.21421387 | C43: =Escenarios!$B$33 -> 367.41984 | D43: =Escenarios!$B$37 -> 0.41220926 | E43: =Escenarios!$B$39 -> 1.2094267
A44: Conservador | B44: =Escenarios!$C$31 -> 0.062952682 | C44: =Escenarios!$C$33 -> -396.60213 | D44: =Escenarios!$C$37 -> 0.016139976 | E44: =Escenarios!$C$39 -> 0.79546539 | F44: Beneficios según su respaldo, haciendo la etapa 2 de todos modos.
A45: Conservador con compuerta | B45: =Escenarios!$D$31 -> 0.057937208 | C45: =Escenarios!$D$33 -> -209.22818 | D45: =Escenarios!$D$37 -> 0.0064963028 | E45: =Escenarios!$D$39 -> 0.5906165 | F45: Beneficios según su respaldo; la compuerta detiene la etapa 2.
A46: Adverso combinado | B46: =Escenarios!$V$31 -> 0.09300273 | C46: =Escenarios!$V$33 -> -240.57876 | D46: =Escenarios!$V$37 -> 0.092323305 | E46: =Escenarios!$V$39 -> 0.78943947 | F46: Tres supuestos malos a la vez: es la prueba más dura.
A47: Inflación persistente | B47: =Escenarios!$N$31 -> 0.23525123 | C47: =Escenarios!$N$33 -> 391.67116 | D47: =Escenarios!$N$37 -> 0.42760989 | E47: =Escenarios!$N$39 -> 1.1945178 | F47: La inflación se queda cerca del 6,5 % hasta 2037.
A48: Renta 30 % | B48: =Escenarios!$Q$31 -> 0.2250889 | C48: =Escenarios!$Q$33 -> 396.09283 | D48: =Escenarios!$Q$37 -> 0.42432534 | E48: =Escenarios!$Q$39 -> 1.2332549 | F48: Si prospera la reducción de impuestos anunciada.
A49: Crédito ordinario | B49: =Escenarios!$R$31 -> 0.21421387 | C49: =Escenarios!$R$33 -> 323.12592 | D49: =Escenarios!$R$37 -> 0.39182372 | E49: =Escenarios!$R$39 -> 1.1687911 | F49: Sin la línea de fomento.
A50: Garantía del FNG | B50: =Escenarios!$S$31 -> 0.21421387 | C50: =Escenarios!$S$33 -> 302.64226 | D50: =Escenarios!$S$37 -> 0.37457397 | E50: =Escenarios!$S$39 -> 1.1606656 | F50: Si el banco no acepta la prenda.
A51: Sin crédito fiscal por innovación | B51: =Escenarios!$T$31 -> 0.17926805 | C51: =Escenarios!$T$33 -> 213.60067 | D51: =Escenarios!$T$37 -> 0.28038084 | E51: =Escenarios!$T$39 -> 1.2094267 | F51: Si el CNBT no certifica la inversión.
A52: Sin las dos gestiones | B52: =Escenarios!$U$31 -> 0.17926805 | C52: =Escenarios!$U$33 -> 150.26438 | D52: =Escenarios!$U$37 -> 0.25681294 | E52: =Escenarios!$U$39 -> 1.1606656 | F52: Ninguna de las dos gestiones sale.
A53: Primera compuerta no superada: solo la etapa 0 | C53: =Herramientas!B36 -> 84.568705 | F53: La etapa 0 es organizacional, no compra equipos ni usa crédito. Positiva con los ahorros conservadores supuestos; su sensibilidad está en la hoja Herramientas.
A55: Riesgos principales y respuesta
A56: Riesgo | B56: Dónde pega en el modelo | F56: Respuesta
A57: El rendimiento o la grasa no mejoran lo esperado | B57: Beneficios de la etapa 1 | F57: La etapa 0 mide la línea base antes de comprar; la etapa 2 solo se aprueba si la etapa 1 cumple (compuerta).
A58: La hiladora cuesta más que el estimado | B58: Inversión del año 1 | F58: Cotización formal antes de la compuerta; los imprevistos de 15 % cubren parte; la etapa 2 se puede aplazar sin perder la etapa 1.
A59: Nadie compra el suero a $45/kg | B59: Beneficio del suero | F59: Dos cotizaciones de fábricas de alimento en la etapa 0; si no hay contrato, el enfriador no se compra.
A60: No se dan las vacantes del relevo natural | B60: Relevo natural | F60: Los operarios se forman y se reubican en yogur o UHT; el escenario Sin relevo natural muestra el efecto.
A61: Sube el gas o la energía (importaciones de gas, El Niño) | B61: Costos operativos nuevos | F61: El escenario Costos operativos +30 % y el punto de equilibrio muestran cuánto aguanta el proyecto.
...

Sheet Herramientas
A1: Herramientas económicas de la oferta
A2: Lo que se hace con ingeniería económica, sin comprar equipos ni cambiar líneas, para que el valor de la propuesta no dependa de supuestos mal analizados. Se calcula con la hoja Escenarios.
A4: Herramientas, una sobre otra
A5: Paso | B5: Costo de capital | C5: VPN ($ M de 2026) | D5: TIR en pesos corrientes | E5: TIR del inversionista | F5: Cobertura mínima | G5: Estado y base
A6: Punto de partida: costo de capital de 16 %, todo depreciado a 10 años, garantía del FNG | B6: =Escenarios!$W$25 -> 0.16 | C6: =Escenarios!$W$33 -> 72.665882 | D6: =Escenarios!$W$31 -> 0.17427009 | E6: =Escenarios!$W$37 -> 0.24052487 | F6: =Escenarios!$W$39 -> 1.1634435 | G6: Referencia.
A7: + Costo de capital con la deuda que financia el proyecto | B7: =Escenarios!$X$25 -> 0.14992986 | C7: =Escenarios!$X$33 -> 128.42404 | D7: =Escenarios!$X$31 -> 0.17427009 | E7: =Escenarios!$X$37 -> 0.24052487 | F7: =Escenarios!$X$39 -> 1.1634435 | G7: El 16 % usaba el 18 % de la deuda actual de la empresa; el proyecto se financia con Bancóldex al 14,1 % más la garantía.
A8: + Depreciación por tipo de activo y gastos deducibles en el año | B8: =Escenarios!$U$25 -> 0.14992986 | C8: =Escenarios!$U$33 -> 150.26438 | D8: =Escenarios!$U$31 -> 0.17926805 | E8: =Escenarios!$U$37 -> 0.25681294 | F8: =Escenarios!$U$39 -> 1.1606656 | G8: Art. 137 ET: equipo de cómputo y redes al 20 % anual; el diagnóstico, la formación y el aval son gastos del año.
A9: + Prenda sobre los equipos en lugar de la garantía del FNG | B9: =Escenarios!$T$25 -> 0.139155 | C9: =Escenarios!$T$33 -> 213.60067 | D9: =Escenarios!$T$31 -> 0.17926805 | E9: =Escenarios!$T$37 -> 0.28038084 | F9: =Escenarios!$T$39 -> 1.2094267 | G9: Gestión de IntegraMotion ante el banco (Ley 1676 de 2013).
A10: + Crédito fiscal por innovación (art. 256-1 ET) | B10: =Escenarios!$B$25 -> 0.139155 | C10: =Escenarios!$B$33 -> 367.41984 | D10: =Escenarios!$B$31 -> 0.21421387 | E10: =Escenarios!$B$37 -> 0.41220926 | F10: =Escenarios!$B$39 -> 1.2094267 | G10: Gestión de IntegraMotion ante Minciencias y el CNBT: 50 % de la parte de desarrollo de la etapa 1.
A11: Cada fila suma la herramienta a las de arriba; todas están en la oferta. Las dos primeras corrigen el análisis; las dos últimas son gestiones que IntegraMotion hace por el cliente.
A13: Cómo se consiguen las dos gestiones
A14: • Prenda sobre los equipos: avalúo de los equipos financiados, contrato de garantía mobiliaria inscrito en el registro de Confecámaras (Ley 1676 de 2013) y póliza todo riesgo endosada al banco. Argumento ante el banco: $6.500 M en activos fijos y deuda de 0,8 veces el EBITDA. Costo: avalúo y registro, y la póliza dentro de los costos operativos.
A15: • Crédito fiscal por innovación (art. 256-1): Lácteos Fúquene es mediana empresa. Se formula el proyecto de innovación (corte del cuajo con sensor de coagulación y modelo de control, estandarización de grasa por balance de masa en línea y MES) y se postula en la convocatoria de beneficios tributarios de Minciencias antes de ejecutarlo, con el aval de un actor reconocido. El CNBT certifica la inversión y el crédito se compensa con impuestos nacionales en los dos años siguientes (o en títulos TIDIS si supera 1.000 UVT).
A16: • Base del crédito: solo la parte de desarrollo; la compra de equipos estándar (controladora de peso, medidor de grasa, tina básica) no califica. Responsable: ingeniero de gestión y finanzas, como entregable del contrato 1.
A18: Propuestas operativas y organizacionales que aseguran los beneficios
A19: Propuesta | B19: Efecto en el VPN ($ M) | G19: Qué asegura
A20: Arranque de la etapa 1 a mitad de 2027 | B20: =Escenarios!$B$33-Escenarios!$E$33 -> 29.35785 | G20: El contrato 1 dura 4 meses. Se ganan 4 meses de beneficio y la compuerta de diciembre se decide con datos medidos, no con promesas.
A21: Línea base medida con un protocolo de medida y verificación (etapa 0) | G21: Responsable: jefe de quesería con el ingeniero de procesos. Indicadores normalizados para que no se confundan con cambios de volumen o de mezcla: horas extra por tonelada, mantenimiento por hora de operación, merma y sobrepeso por producto y lote, rendimiento por litro y por receta; registro diario en el MES y revisión mensual.
A22: Relevo con la rotación normal de la planta | B22: =Quesería!$B$14*Quesería!$E$102 -> 21.6 | G22: Con unas 100 personas y 15 % o más de rotación hay unas 15 vacantes al año. Cubrir 2 con operarios ya formados ahorra además el costo de reemplazo (valor del año 2 en la columna).
A23: Contrato del suero antes de comprar el enfriador | G23: El beneficio del suero pasa a "contratado"; si no hay comprador, no se compra el equipo.
A24: Utilidad de IntegraMotion atada a los resultados | G24: Propuesta de contrato: la utilidad del AIU (unos $8 M del contrato 1) queda contingente. Se paga completa si el beneficio verificado a 12 meses llega al 80 % de la meta, en proporción entre 50 % y 80 %, y nada por debajo de 50 %. No está en el VPN de la quesería, que la paga completa.
A25: Bonificación del equipo de la quesería por metas | G25: Se paga solo de ahorro ya verificado en merma, sobrepeso y rendimiento; su monto se fija en la etapa 0. No está en el VPN: al definirlo se resta del beneficio.
